Workbook
Name VK: 'Virgin Stock'!$A$2:$I$501
Name SK: 'Semi Stock'!$A$2:$I$501
Name VIRGIN: 'Virgin Stock'!$B$2:$J$501
Name SKP: Semi!$A$4:$I$520
Name semi: Semi!$B$3:$BZ$7
Name vksearch: Virgin!$A$4:$J$16
Name SK: Semi!$A$2:$I$520
Name ITEMLIST: 'FG Stock'!$B:$B
Name vksearch: 'Virgin Stock'!$A$6:$J$501
Name semi: 'Semi Stock'!$B$3:$K$10
Name FILTER: #REF!
Name SEMIKRAFT: Semi!$B$2:$J$520
Name __xludf.DUMMYFUNCTION: #REF!
Name sksearch: Semi!$A$4:$J$520
Name VIRGIN: Virgin!$B$2:$J$16
Name FG: WFG!$B$2:$G$418
Name FG: 'FG Stock'!$B$2:$G$540
Name SEMIKRAFT: 'Semi Stock'!$B$2:$J$501
Name ITEMLIST: WFG!$B:$B
Name VK: Virgin!$A$2:$I$16
Name sksearch: 'Semi Stock'!$A$5:$J$501
Name SKP: 'Semi Stock'!$A$5:$I$501

Sheet MR
A1: PROFIT & LOSS REPORT FOR THE M/O JULY, 2026
B2: OPENING | D2: PURCHASE | F2: CONSUMPTION | H2: CLOSING
A3: PAPER | B3: Opn Stock | C3: Opn Amt | D3: Purchase Qty | E3: Purchase Amt | F3: Consumption Qty | G3: Consumption Amt | H3: Closing Qty | I3: Closing Amt
A4: Semi Kraft | B4: =Semi!F1 -> 46016 | C4: =Semi!BV1 -> 1242115.4 | D4: =Semi!G1 -> 2215 | E4: =Semi!BW1 -> 64933.5 | F4: =Semi!H1 -> 9606 | G4: =Semi!BX1 -> 303896.68 | H4: =Semi!I1 -> 38625 | I4: =Semi!BY1 -> 1242115.4
A5: Virgin Kraft | B5: =Virgin!F1 -> 63229 | C5: =Virgin!BV1 -> 2365180.8 | D5: =Virgin!G1 -> 5037 | E5: =Virgin!BW1 -> 14872 | F5: =Virgin!H1 -> 18476 | G5: =Virgin!BX1 -> 542957.75 | H5: =Virgin!I1 -> 49790 | I5: =Virgin!BY1 -> 1837095
A6: Chennai | B6: =Dup!F1 -> 2251 | C6: =Dup!BU1 -> 135850.5 | D6: =Dup!G1 -> 0 | E6: =Dup!BV1 -> 0 | F6: =Dup!H1 -> 0 | G6: =Dup!BW1 -> 0 | H6: =Dup!I1 -> 2251 | I6: =Dup!BX1 -> 135850.5
B8: =B4+B5+B6+B7 -> 111496 | C8: =C4+C5+C6+C7 -> 3743146.6 | D8: =D4+D5+D6+D7 -> 7252 | E8: =E4+E5+E6+E7 -> 79805.5 | F8: =F4+F5+F6+F7 -> 28082 | G8: =G4+G5+G6+G7 -> 846854.43 | H8: =H4+H5+H6+H7 -> 90666 | I8: =I4+I5+I6+I7 -> 3215060.9
A10: TOTAL SALE | F10: Without GST | G10: With GST | H10: Difference
B11: Without GST | C11: With GST | E11: Paper Used | F11: =G8 -> 846854.43 | G11: =F11+(F11*18%) -> 999288.23 | H11: Without GST | I11: With GST
A12: =Summarry!B23 -> Diya Industries | B12: =Summarry!C23 | C12: =B12*(B12*18%) -> 0 | E12: =A12 -> Diya Industries | F12: =Summarry!D23 -> 39905 | G12: =F12+(F12*18%) -> 47087.9 | H12: =B12-F12 -> -39905 | I12: =C12-G12 -> -47087.9
A13: =Summarry!B24 -> PACKAGING INDIA | B13: =Summarry!C24 -> 0 | C13: =B13*(B13*18%) -> 0 | E13: =A13 -> PACKAGING INDIA | F13: =Summarry!D24 -> 113884 | G13: =F13+(F13*18%) -> 134383.12 | H13: =B13-F13 -> -113884 | I13: =C13-G13 -> -134383.12
A14: =Summarry!B25 -> RADHE RADHE | B14: =Summarry!C25 | C14: =B14+(B14*18%) -> 0 | E14: =A14 -> RADHE RADHE | F14: =Summarry!D25 | G14: =F14+(F14*18%) -> 0 | H14: =B14-F14 -> 0 | I14: =C14-G14 -> 0
A15: PI | B15: =Summarry!C26 -> 0 | C15: =B15*(B15*18%) -> 0 | E15: =A15 -> PI | F15: =Summarry!D26 | G15: =F15+(F15*5%) -> 0 | H15: =B15-F15 -> 0 | I15: =C15-G15 -> 0
A16: SCRAP(CASH) | B16: =Summarry!C27 -> 524594 | C16: =B16 -> 524594 | E16: SCRAP(CASH) | F16: =Summarry!D27 | G16: =F16+(F16*12%) -> 0 | H16: =B16-F16 -> 524594 | I16: =C16-G16 -> 524594
A17: TALLY DATA | B17: =Summarry!C28 -> 9764926 | C17: =Summarry!D28 -> 10264565 | E17: G. Total Purchase | F17: =F11+F12+F13+F14+F15+F16 -> 1000643.4 | G17: =G11+G12+G13+G14+G15+G16 -> 1180759.2 | H17: =B19-F17 -> 8506364.6 | I17: =C19-G17 -> 8812810.8
A18: CREDIT NOTE | B18: 257918 | C18: 270995 | E18: Bank Charges | H18: =Summarry!C3
A19: NETT SALE | B19: =B17-B18 -> 9507008 | C19: =C17-C18 -> 9993570 | E19: Interest on OD A/c | H19: =Summarry!C4 -> 120154
A20: TOTAL PURCHASE | E20: Freight Outward Charges | H20: =Summarry!C5 -> 237130
B21: Without GST | C21: With GST | E21: Salary with Director Remuneration | H21: =Summarry!C6 -> 282277
A22: Current Month Purchase | B22: =Summarry!C36 | C22: =Summarry!D36 | E22: Client Welfare / Commission | H22: =Summarry!C7
E23: Staff Welfare & Pantry Exp. | H23: =Summarry!C8 -> 0
E24: Freight Inward Charges | H24: =Summarry!C9 -> 15500
E25: Conveyance & Bike Petrol Expense | H25: =Summarry!C10 -> 1040
E26: AMC Charges and Factory Insurance Exp | H26: =Summarry!C11 -> 9500
A27: TOTAL SCRAP RATIO ON CONSUMPTION | E27: Machine Exp | H27: =Summarry!C12 -> 16394
E28: Factory Rent Exp | H28: =Summarry!C13 -> 199000
E29: Plant Exp | H29: =Summarry!C14
E30: Office & Stationery Exp | H30: =Summarry!C15 -> 4890
E31: Legal Expenses | H31: =Summarry!C16 -> 3000
E32: DG Diesel | H32: =Summarry!C17 -> 30000
A33: Finish Goods Stock | C33: =Summarry!C29 -> 1492974.7 | E33: DG Rent | H33: =Summarry!C18 -> 12000
A34: Non-Moving Stock | C34: =Summarry!C30 -> 1470807.7 | E34: Electricity Bill | H34: =Summarry!C19 -> 122280
A35: Work in Process Stock | C35: =Summarry!C31 -> 1341382.4 | E35: LPG Cylinder | H35: =Summarry!C20 -> 0
A36: Paper Stock | C36: =Summarry!C32+Summarry!C33+Summarry!C34 -> 3215060.9 | E36: Forklift Diesel | H36: =Summarry!C21 -> 0
A37: Raw material Stock | C37: =Summarry!C35 -> 375402.88 | E37: Consumable Goods (Excl. Gas) | H37: =Summarry!C22 -> 433075 | I37: =H18+H19+H20+H21+H22+H23+H24+H25+H26+H27+H28+H29+H30+H31+H32+H33+H34+H35+H36+H37 -> 1486240
A38: Grand Total Stock | C38: =C33+C34+C35+C36+C37 -> 7895628.5 | E38: NET PROFIT | H38: =H17-I37 -> 7020124.6

Sheet Summarry
A1: PACKWELL INDIA DETAILS FOR MONTHLY REPORT
A2: S. No. | B2: Particulars | C2: Expenses Amount | F2: AUG | G2: Employee | H2: DIARY & Refreshment | I2: Employee Dinner | J2: 70 | K2: DG | L2: Forklift
A3: 1 | B3: =MR!E18 -> Bank Charges | F3: 1
A4: 2 | B4: =MR!E19 -> Interest on OD A/c | C4: 120154 | F4: 2
A5: 3 | B5: =MR!E20 -> Freight Outward Charges | C5: =Freight!M125 -> 237130 | F5: 3
A6: 4 | B6: =MR!E21 -> Salary with Director Remuneration | C6: =Wages!J51 -> 282277 | F6: 4
A7: 5 | B7: =MR!E22 -> Client Welfare / Commission | F7: 5
A8: 6 | B8: =MR!E23 -> Staff Welfare & Pantry Exp. | C8: =J36+H36 -> 0 | F8: 6
A9: 7 | B9: =MR!E24 -> Freight Inward Charges | C9: =6000+9500 -> 15500 | F9: 7
A10: 8 | B10: =MR!E25 -> Conveyance & Bike Petrol Expense | C10: =840+200 -> 1040 | F10: 8
A11: 9 | B11: =MR!E26 -> AMC Charges and Factory Insurance Exp | C11: =4000+2500+3000 -> 9500 | F11: 9
A12: 10 | B12: =MR!E27 -> Machine Exp | C12: 16394 | F12: 10
A13: 11 | B13: =MR!E28 -> Factory Rent Exp | C13: 199000 | F13: 11
A14: 12 | B14: =MR!E29 -> Plant Exp | F14: 12
A15: 13 | B15: =MR!E30 -> Office & Stationery Exp | C15: 4890 | F15: 13
A16: 14 | B16: =MR!E31 -> Legal Expenses | C16: 3000 | F16: 14
A17: 15 | B17: =MR!E32 -> DG Diesel | C17: 30000 | F17: 15
A18: 16 | B18: =MR!E33 -> DG Rent | C18: 12000 | F18: 16
A19: 17 | B19: =MR!E34 -> Electricity Bill | C19: 122280 | F19: 17
A20: 18 | B20: =MR!E35 -> LPG Cylinder | C20: =RM!BT14 -> 0 | F20: 18
A21: 19 | B21: =MR!E36 -> Forklift Diesel | C21: =L36 -> 0 | F21: 19
A22: 20 | B22: =MR!E37 -> Consumable Goods (Excl. Gas) | C22: =RM!BV19 -> 433075 | F22: 20
A23: 21 | B23: Diya Industries | D23: 39905 | F23: 21
A24: 22 | B24: PACKAGING INDIA | C24: 0 | D24: 113884 | F24: 22
A25: 23 | B25: RADHE RADHE | F25: 23
A26: 24 | B26: PACKAGING INDIA | C26: 0 | F26: 24
A27: 25 | B27: SCRAP | C27: =Scrap!E21 -> 524594 | F27: 25
A28: 26 | B28: Sale | C28: 9764926 | D28: 10264565 | F28: 26
A29: 27 | B29: FINISH GOODS | C29: =WFG!BV1 -> 1492974.7 | D29: =C29+C30+C31 -> 4305164.8 | F29: 27
A30: 28 | B30: NON MOVING FINISH GOODS | C30: =DFG!BT1 -> 1470807.7 | F30: 28
A31: 29 | B31: WIP | C31: =WIP!K75 -> 1341382.4 | F31: 29
A32: 30 | B32: Semi Paper Stock | C32: =Semi!BY1 -> 1242115.4 | D32: =C32+C33+C34+C35 -> 3590463.8 | F32: 30
A33: 31 | B33: Virgin Paper Stock | C33: =Virgin!BY1 -> 1837095 | F33: 31 | J33: =I33*J2 -> 0
A34: 32 | B34: Chennai Paper Stock | C34: =Dup!BX1 -> 135850.5 | F34: 32
A35: 33 | B35: Raw Material Stock | C35: =RM!BU1 -> 375402.88 | G35: DIARY | J35: =I35*70 -> 0
A36: 34 | B36: Purchase | F36: Total | G36: =SUM(G3:G35) -> 0 | H36: =SUM(H3:H35) -> 0 | I36: =SUM(I3:I35) -> 0 | J36: =SUM(J3:J35) -> 0 | K36: =SUM(K3:K35) -> 0 | L36: =SUM(L3:L35) -> 0
A37: 35
A38: 36
A39: 37
A40: 38

Sheet Wages
A2: PACKWELL WAGES SHEET FOR THE MONTH OF JULY - 2026 | F2: 31 | H2: 248 | K2: 1 | N2: 2 | Q2: 3 | T2: 4 | W2: 5 | Z2: 6 | AC2: 7 | AF2: 8 | AI2: 9 | AL2: 10 | AO2: 11 | AR2: 12 | AU2: 13 | AX2: 14 | BA2: 15 | BD2: 16 | BG2: 17 | BJ2: 18 | BM2: 19 | BP2: 20 | BS2: 21 | BV2: 22 | BY2: 23 | CB2: 24 | CE2: 25 | CH2: 26 | CK2: 27 | CN2: 28 | CQ2: 29 | CT2: 30 | CW2: 31 | CZ2: 1
A3: S.No. | B3: Employee Name | C3: Designation | D3: Basic Salary | E3: 31 | F3: Days Amount | G3: 248 | H3: OT Amount | I3: Gross Salary | J3: Gross Income | K3: Day's | L3: OT | M3: Gross Salary | N3: Day's Amount | O3: OT Amount | P3: Salary | Q3: Day's | R3: OT | S3: Gross Salary | T3: Day's | U3: OT | V3: Gross Salary | W3: Day's | X3: OT | Y3: Gross Salary | Z3: Day's | AA3: OT | AB3: Gross Salary | AC3: Day's | AD3: OT | AE3: Gross Salary | AF3: Day's | AG3: OT | AH3: Gross Salary | AI3: Day's | AJ3: OT | AK3: Gross Salary | AL3: Day's | AM3: OT | AN3: Gross Salary | AO3: Day's | AP3: OT | AQ3: Gross Salary | AR3: Day's | AS3: OT | AT3: Gross Salary | AU3: Day's | AV3: OT | AW3: Gross Salary | AX3: Day's | AY3: OT | AZ3: Gross Salary | BA3: Day's | BB3: OT | BC3: Gross Salary | BD3: Day's | BE3: OT | BF3: Gross Salary | BG3: Day's | BH3: OT | BI3: Gross Salary | BJ3: Day's | BK3: OT | BL3: Gross Salary | BM3: Day's | BN3: OT | BO3: Gross Salary | BP3: Day's | BQ3: OT | BR3: Gross Salary | BS3: Day's | BT3: OT | BU3: Gross Salary | BV3: Day's | BW3: OT | BX3: Gross Salary | BY3: Day's | BZ3: OT | CA3: Gross Salary | CB3: Day's | CC3: OT | CD3: Gross Salary | CE3: Day's | CF3: OT | CG3: Gross Salary | CH3: Day's | CI3: OT | CJ3: Gross Salary | CK3: Day's | CL3: OT | CM3: Gross Salary | CN3: Day's | CO3: OT | CP3: Gross Salary | CQ3: Day's | CR3: OT | CS3: Gross Salary | CT3: Day's | CU3: OT | CV3: Gross Salary | CW3: Day's | CX3: OT | CY3: Gross Salary | CZ3: Day's | DA3: OT | DB3: Gross Salary
A4: 1 | B4: Mr Jitender Ji | C4: Director | D4: 75000 | E4: =K4+N4+Q4+T4+W4+Z4+AC4+AF4+AI4+AL4+AO4+AR4+AU4+AX4+BA4+BD4+BG4+BJ4+BM4+BP4+BS4+BV4+BY4+CB4+CE4+CH4+CK4+CN4+CQ4+CT4+CW4+CZ4 -> 7 | F4: =ROUND(D4/$F$2*E4,0) -> 16935 | G4: =L4+O4+R4+U4+X4+AA4+AD4+AG4+AJ4+AM4+AP4+AS4+AV4+AY4+BB4+BE4+BH4+BK4+BN4+BQ4+BT4+BW4+BZ4+CC4+CF4+CI4+CL4+CO4+CR4+CU4+CX4+DA4 -> 0 | H4: =ROUND(D4/$H$2*G4,0) -> 0 | I4: =F4+H4 -> 16935 | J4: =M4+P4+S4+V4+Y4+AB4+AE4+AH4+AK4+AN4+AQ4+AT4+AW4+AZ4+BC4+BF4+BI4+BL4+BO4+BR4+BU4+BX4+CA4+CD4+CG4+CJ4+CM4+CP4+CS4+CV4+CY4 -> 16933 | K4: 1 | M4: =ROUND((($D$4/$E$3*K4)+($D$4/$H$2*L4)),0) -> 2419 | N4: 1 | P4: =ROUND(($D$4/$E$3*N4)+($D$4/$H$2*O4),0) -> 2419 | Q4: 1 | S4: =ROUND(($D$4/$E$3*Q4)+($D$4/$H$2*R4),0) -> 2419 | T4: 1 | V4: =ROUND(($D$4/$E$3*T4)+($D$4/$H$2*U4),0) -> 2419 | W4: 1 | Y4: =ROUND(($D$4/$E$3*W4)+($D$4/$H$2*X4),0) -> 2419 | Z4: 1 | AB4: =ROUND(($D$4/$E$3*Z4)+($D$4/$H$2*AA4),0) -> 2419 | AC4: 1 | AE4: =ROUND(($D$4/$E$3*AC4)+($D$4/$H$2*AD4),0) -> 2419 | AH4: =ROUND(($D$4/$E$3*AF4)+($D$4/$H$2*AG4),0) -> 0 | AK4: =ROUND(($D$4/$E$3*AI4)+($D$4/$H$2*AJ4),0) -> 0 | AN4: =ROUND(($D$4/$E$3*AL4)+($D$4/$H$2*AM4),0) -> 0 | AQ4: =ROUND(($D$4/$E$3*AO4)+($D$4/$H$2*AP4),0) -> 0 | AT4: =ROUND(($D$4/$E$3*AR4)+($D$4/$H$2*AS4),0) -> 0 | AW4: =ROUND(($D$4/$E$3*AU4)+($D$4/$H$2*AV4),0) -> 0 | AZ4: =ROUND(($D$4/$E$3*AX4)+($D$4/$H$2*AY4),0) -> 0 | BC4: =ROUND(($D$4/$E$3*BA4)+($D$4/$H$2*BB4),0) -> 0 | BF4: =ROUND(($D$4/$E$3*BD4)+($D$4/$H$2*BE4),0) -> 0 | BI4: =ROUND(($D$4/$E$3*BG4)+($D$4/$H$2*BH4),0) -> 0 | BL4: =ROUND(($D$4/$E$3*BJ4)+($D$4/$H$2*BK4),0) -> 0 | BO4: =ROUND(($D$4/$E$3*BM4)+($D$4/$H$2*BN4),0) -> 0 | BR4: =ROUND(($D$4/$E$3*BP4)+($D$4/$H$2*BQ4),0) -> 0 | BU4: =ROUND(($D$4/$E$3*BS4)+($D$4/$H$2*BT4),0) -> 0 | BX4: =ROUND(($D$4/$E$3*BV4)+($D$4/$H$2*BW4),0) -> 0 | CA4: =ROUND(($D$4/$E$3*BY4)+($D$4/$H$2*BZ4),0) -> 0 | CD4: =ROUND(($D$4/$E$3*CB4)+($D$4/$H$2*CC4),0) -> 0 | CG4: =ROUND(($D$4/$E$3*CE4)+($D$4/$H$2*CF4),0) -> 0 | CJ4: =ROUND(($D$4/$E$3*CH4)+($D$4/$H$2*CI4),0) -> 0 | CM4: =ROUND(($D$4/$E$3*CK4)+($D$4/$H$2*CL4),0) -> 0 | CP4: =ROUND(($D$4/$E$3*CN4)+($D$4/$H$2*CO4),0) -> 0 | CS4: =ROUND(($D$4/$E$3*CQ4)+($D$4/$H$2*CR4),0) -> 0 | CV4: =ROUND(($D$4/$E$3*CT4)+($D$4/$H$2*CU4),0) -> 0 | CY4: =ROUND(($D$4/$E$3*CW4)+($D$4/$H$2*CX4),0) -> 0 | DB4: =ROUND(($D$4/$E$3*CZ4)+($D$4/$H$2*DA4),0) -> 0
A5: 2 | B5: Rajiv Pal | C5: Accounts/HR | D5: 37500 | E5: =K5+N5+Q5+T5+W5+Z5+AC5+AF5+AI5+AL5+AO5+AR5+AU5+AX5+BA5+BD5+BG5+BJ5+BM5+BP5+BS5+BV5+BY5+CB5+CE5+CH5+CK5+CN5+CQ5+CT5+CW5+CZ5 -> 7 | F5: =ROUND(D5/$F$2*E5,0) -> 8468 | G5: =L5+O5+R5+U5+X5+AA5+AD5+AG5+AJ5+AM5+AP5+AS5+AV5+AY5+BB5+BE5+BH5+BK5+BN5+BQ5+BT5+BW5+BZ5+CC5+CF5+CI5+CL5+CO5+CR5+CU5+CX5+DA4 -> 0 | H5: =ROUND(D5/$H$2*G5,0) -> 0 | I5: =F5+H5 -> 8468 | J5: =M5+P5+S5+V5+Y5+AB5+AE5+AH5+AK5+AN5+AQ5+AT5+AW5+AZ5+BC5+BF5+BI5+BL5+BO5+BR5+BU5+BX5+CA5+CD5+CG5+CJ5+CM5+CP5+CS5+CV5+CY5 -> 8470 | K5: 1 | M5: =ROUND(($D$5/$E$3*K5)+($D$5/$H$2*L5),0) -> 1210 | N5: 1 | P5: =ROUND(($D$5/$E$3*N5)+($D$5/$H$2*O5),0) -> 1210 | Q5: 1 | S5: =ROUND(($D$5/$E$3*Q5)+($D$5/$H$2*R5),0) -> 1210 | T5: 1 | V5: =ROUND(($D$5/$E$3*T5)+($D$5/$H$2*U5),0) -> 1210 | W5: 1 | Y5: =ROUND(($D$5/$E$3*W5)+($D$5/$H$2*X5),0) -> 1210 | Z5: 1 | AB5: =ROUND(($D$5/$E$3*Z5)+($D$5/$H$2*AA5),0) -> 1210 | AC5: 1 | AE5: =ROUND(($D$5/$E$3*AC5)+($D$5/$H$2*AD5),0) -> 1210 | AH5: =ROUND(($D$5/$E$3*AF5)+($D$5/$H$2*AG5),0) -> 0 | AK5: =ROUND(($D$5/$E$3*AI5)+($D$5/$H$2*AJ5),0) -> 0 | AN5: =ROUND(($D$5/$E$3*AL5)+($D$5/$H$2*AM5),0) -> 0 | AQ5: =ROUND(($D$5/$E$3*AO5)+($D$5/$H$2*AP5),0) -> 0 | AT5: =ROUND(($D$5/$E$3*AR5)+($D$5/$H$2*AS5),0) -> 0 | AW5: =ROUND(($D$5/$E$3*AU5)+($D$5/$H$2*AV5),0) -> 0 | AZ5: =ROUND(($D$5/$E$3*AX5)+($D$5/$H$2*AY5),0) -> 0 | BC5: =ROUND(($D$5/$E$3*BA5)+($D$5/$H$2*BB5),0) -> 0 | BF5: =ROUND(($D$5/$E$3*BD5)+($D$5/$H$2*BE5),0) -> 0 | BI5: =ROUND(($D$5/$E$3*BG5)+($D$5/$H$2*BH5),0) -> 0 | BL5: =ROUND(($D$5/$E$3*BJ5)+($D$5/$H$2*BK5),0) -> 0 | BO5: =ROUND(($D$5/$E$3*BM5)+($D$5/$H$2*BN5),0) -> 0 | BR5: =ROUND(($D$5/$E$3*BP5)+($D$5/$H$2*BQ5),0) -> 0 | BU5: =ROUND(($D$5/$E$3*BS5)+($D$5/$H$2*BT5),0) -> 0 | BX5: =ROUND(($D$5/$E$3*BV5)+($D$5/$H$2*BW5),0) -> 0 | CA5: =ROUND(($D$5/$E$3*BY5)+($D$5/$H$2*BZ5),0) -> 0 | CD5: =ROUND(($D$5/$E$3*CB5)+($D$5/$H$2*CC5),0) -> 0 | CG5: =ROUND(($D$5/$E$3*CE5)+($D$5/$H$2*CF5),0) -> 0 | CJ5: =ROUND(($D$5/$E$3*CH5)+($D$5/$H$2*CI5),0) -> 0 | CM5: =ROUND(($D$5/$E$3*CK5)+($D$5/$H$2*CL5),0) -> 0 | CP5: =ROUND(($D$5/$E$3*CN5)+($D$5/$H$2*CO5),0) -> 0 | CS5: =ROUND(($D$5/$E$3*CQ5)+($D$5/$H$2*CR5),0) -> 0 | CV5: =ROUND(($D$5/$E$3*CT5)+($D$5/$H$2*CU5),0) -> 0 | CY5: =ROUND(($D$5/$E$3*CW5)+($D$5/$H$2*CX5),0) -> 0 | DB5: =ROUND(($D$5/$E$3*CZ5)+($D$5/$H$2*DA5),0) -> 0
A6: 3 | B6: Shubham Singh | C6: Production Head | D6: 41500 | E6: =K6+N6+Q6+T6+W6+Z6+AC6+AF6+AI6+AL6+AO6+AR6+AU6+AX6+BA6+BD6+BG6+BJ6+BM6+BP6+BS6+BV6+BY6+CB6+CE6+CH6+CK6+CN6+CQ6+CT6+CW6+CZ6 -> 7 | F6: =ROUND(D6/$F$2*E6,0) -> 9371 | G6: =L6+O6+R6+U6+X6+AA6+AD6+AG6+AJ6+AM6+AP6+AS6+AV6+AY6+BB6+BE6+BH6+BK6+BN6+BQ6+BT6+BW6+BZ6+CC6+CF6+CI6+CL6+CO6+CR6+CU6+CX6+DA5 -> 0 | H6: =ROUND(D6/$H$2*G6,0) -> 0 | I6: =F6+H6 -> 9371 | J6: =M6+P6+S6+V6+Y6+AB6+AE6+AH6+AK6+AN6+AQ6+AT6+AW6+AZ6+BC6+BF6+BI6+BL6+BO6+BR6+BU6+BX6+CA6+CD6+CG6+CJ6+CM6+CP6+CS6+CV6+CY6 -> 9373 | K6: 1 | M6: =ROUND(($D$6/$E$3*K6)+($D$6/$H$2*L6),0) -> 1339 | N6: 1 | P6: =ROUND(($D$6/$E$3*N6)+($D$6/$H$2*O6),0) -> 1339 | Q6: 1 | S6: =ROUND(($D$6/$E$3*Q6)+($D$6/$H$2*R6),0) -> 1339 | T6: 1 | V6: =ROUND(($D$6/$E$3*T6)+($D$6/$H$2*U6),0) -> 1339 | W6: 1 | Y6: =ROUND(($D$6/$E$3*W6)+($D$6/$H$2*X6),0) -> 1339 | Z6: 1 | AB6: =ROUND(($D$6/$E$3*Z6)+($D$6/$H$2*AA6),0) -> 1339 | AC6: 1 | AE6: =ROUND(($D$6/$E$3*AC6)+($D$6/$H$2*AD6),0) -> 1339 | AH6: =ROUND(($D$6/$E$3*AF6)+($D$6/$H$2*AG6),0) -> 0 | AK6: =ROUND(($D$6/$E$3*AI6)+($D$6/$H$2*AJ6),0) -> 0 | AN6: =ROUND(($D$6/$E$3*AL6)+($D$6/$H$2*AM6),0) -> 0 | AQ6: =ROUND(($D$6/$E$3*AO6)+($D$6/$H$2*AP6),0) -> 0 | AT6: =ROUND(($D$6/$E$3*AR6)+($D$6/$H$2*AS6),0) -> 0 | AW6: =ROUND(($D$6/$E$3*AU6)+($D$6/$H$2*AV6),0) -> 0 | AZ6: =ROUND(($D$6/$E$3*AX6)+($D$6/$H$2*AY6),0) -> 0 | BC6: =ROUND(($D$6/$E$3*BA6)+($D$6/$H$2*BB6),0) -> 0 | BF6: =ROUND(($D$6/$E$3*BD6)+($D$6/$H$2*BE6),0) -> 0 | BI6: =ROUND(($D$6/$E$3*BG6)+($D$6/$H$2*BH6),0) -> 0 | BL6: =ROUND(($D$6/$E$3*BJ6)+($D$6/$H$2*BK6),0) -> 0 | BO6: =ROUND(($D$6/$E$3*BM6)+($D$6/$H$2*BN6),0) -> 0 | BR6: =ROUND(($D$6/$E$3*BP6)+($D$6/$H$2*BQ6),0) -> 0 | BU6: =ROUND(($D$6/$E$3*BS6)+($D$6/$H$2*BT6),0) -> 0 | BX6: =ROUND(($D$6/$E$3*BV6)+($D$6/$H$2*BW6),0) -> 0 | CA6: =ROUND(($D$6/$E$3*BY6)+($D$6/$H$2*BZ6),0) -> 0 | CD6: =ROUND(($D$6/$E$3*CB6)+($D$6/$H$2*CC6),0) -> 0 | CG6: =ROUND(($D$6/$E$3*CE6)+($D$6/$H$2*CF6),0) -> 0 | CJ6: =ROUND(($D$6/$E$3*CH6)+($D$6/$H$2*CI6),0) -> 0 | CM6: =ROUND(($D$6/$E$3*CK6)+($D$6/$H$2*CL6),0) -> 0 | CP6: =ROUND(($D$6/$E$3*CN6)+($D$6/$H$2*CO6),0) -> 0 | CS6: =ROUND(($D$6/$E$3*CQ6)+($D$6/$H$2*CR6),0) -> 0 | CV6: =ROUND(($D$6/$E$3*CT6)+($D$6/$H$2*CU6),0) -> 0 | CY6: =ROUND(($D$6/$E$3*CW6)+($D$6/$H$2*CX6),0) -> 0 | DB6: =ROUND(($D$6/$E$3*CZ6)+($D$6/$H$2*DA6),0) -> 0
A7: 4 | B7: Raj Kumar | C7: Sup | D7: 40000 | E7: =K7+N7+Q7+T7+W7+Z7+AC7+AF7+AI7+AL7+AO7+AR7+AU7+AX7+BA7+BD7+BG7+BJ7+BM7+BP7+BS7+BV7+BY7+CB7+CE7+CH7+CK7+CN7+CQ7+CT7+CW7+CZ7 -> 7 | F7: =ROUND(D7/$F$2*E7,0) -> 9032 | G7: =L7+O7+R7+U7+X7+AA7+AD7+AG7+AJ7+AM7+AP7+AS7+AV7+AY7+BB7+BE7+BH7+BK7+BN7+BQ7+BT7+BW7+BZ7+CC7+CF7+CI7+CL7+CO7+CR7+CU7+CX7+DA6 -> 0 | H7: =ROUND(D7/$H$2*G7,0) -> 0 | I7: =F7+H7 -> 9032 | J7: =M7+P7+S7+V7+Y7+AB7+AE7+AH7+AK7+AN7+AQ7+AT7+AW7+AZ7+BC7+BF7+BI7+BL7+BO7+BR7+BU7+BX7+CA7+CD7+CG7+CJ7+CM7+CP7+CS7+CV7+CY7 -> 9030 | K7: 1 | M7: =ROUND(($D$7/$E$3*K7)+($D$7/$H$2*L7),0) -> 1290 | N7: 1 | P7: =ROUND(($D$7/$E$3*N7)+($D$7/$H$2*O7),0) -> 1290 | Q7: 1 | S7: =ROUND(($D$7/$E$3*Q7)+($D$7/$H$2*R7),0) -> 1290 | T7: 1 | V7: =ROUND(($D$7/$E$3*T7)+($D$7/$H$2*U7),0) -> 1290 | W7: 1 | Y7: =ROUND(($D$7/$E$3*W7)+($D$7/$H$2*X7),0) -> 1290 | Z7: 1 | AB7: =ROUND(($D$7/$E$3*Z7)+($D$7/$H$2*AA7),0) -> 1290 | AC7: 1 | AE7: =ROUND(($D$7/$E$3*AC7)+($D$7/$H$2*AD7),0) -> 1290 | AH7: =ROUND(($D$7/$E$3*AF7)+($D$7/$H$2*AG7),0) -> 0 | AK7: =ROUND(($D$7/$E$3*AI7)+($D$7/$H$2*AJ7),0) -> 0 | AN7: =ROUND(($D$7/$E$3*AL7)+($D$7/$H$2*AM7),0) -> 0 | AQ7: =ROUND(($D$7/$E$3*AO7)+($D$7/$H$2*AP7),0) -> 0 | AT7: =ROUND(($D$7/$E$3*AR7)+($D$7/$H$2*AS7),0) -> 0 | AW7: =ROUND(($D$7/$E$3*AU7)+($D$7/$H$2*AV7),0) -> 0 | AZ7: =ROUND(($D$7/$E$3*AX7)+($D$7/$H$2*AY7),0) -> 0 | BC7: =ROUND(($D$7/$E$3*BA7)+($D$7/$H$2*BB7),0) -> 0 | BF7: =ROUND(($D$7/$E$3*BD7)+($D$7/$H$2*BE7),0) -> 0 | BI7: =ROUND(($D$7/$E$3*BG7)+($D$7/$H$2*BH7),0) -> 0 | BL7: =ROUND(($D$7/$E$3*BJ7)+($D$7/$H$2*BK7),0) -> 0 | BO7: =ROUND(($D$7/$E$3*BM7)+($D$7/$H$2*BN7),0) -> 0 | BR7: =ROUND(($D$7/$E$3*BP7)+($D$7/$H$2*BQ7),0) -> 0 | BU7: =ROUND(($D$7/$E$3*BS7)+($D$7/$H$2*BT7),0) -> 0 | BX7: =ROUND(($D$7/$E$3*BV7)+($D$7/$H$2*BW7),0) -> 0 | CA7: =ROUND(($D$7/$E$3*BY7)+($D$7/$H$2*BZ7),0) -> 0 | CD7: =ROUND(($D$7/$E$3*CB7)+($D$7/$H$2*CC7),0) -> 0 | CG7: =ROUND(($D$7/$E$3*CE7)+($D$7/$H$2*CF7),0) -> 0 | CJ7: =ROUND(($D$7/$E$3*CH7)+($D$7/$H$2*CI7),0) -> 0 | CM7: =ROUND(($D$7/$E$3*CK7)+($D$7/$H$2*CL7),0) -> 0 | CP7: =ROUND(($D$7/$E$3*CN7)+($D$7/$H$2*CO7),0) -> 0 | CS7: =ROUND(($D$7/$E$3*CQ7)+($D$7/$H$2*CR7),0) -> 0 | CV7: =ROUND(($D$7/$E$3*CT7)+($D$7/$H$2*CU7),0) -> 0 | CY7: =ROUND(($D$7/$E$3*CW7)+($D$7/$H$2*CX7),0) -> 0 | DB7: =ROUND(($D$7/$E$3*CZ7)+($D$7/$H$2*DA7),0) -> 0
A8: 5 | B8: Devesh Chouhan | C8: Lifter/Disp. | D8: 20000 | E8: =K8+N8+Q8+T8+W8+Z8+AC8+AF8+AI8+AL8+AO8+AR8+AU8+AX8+BA8+BD8+BG8+BJ8+BM8+BP8+BS8+BV8+BY8+CB8+CE8+CH8+CK8+CN8+CQ8+CT8+CW8+CZ8 -> 7 | F8: =ROUND(D8/$F$2*E8,0) -> 4516 | G8: =L8+O8+R8+U8+X8+AA8+AD8+AG8+AJ8+AM8+AP8+AS8+AV8+AY8+BB8+BE8+BH8+BK8+BN8+BQ8+BT8+BW8+BZ8+CC8+CF8+CI8+CL8+CO8+CR8+CU8+CX8+DA7 -> 0 | H8: =ROUND(D8/$H$2*G8,0) -> 0 | I8: =F8+H8 -> 4516 | J8: =M8+P8+S8+V8+Y8+AB8+AE8+AH8+AK8+AN8+AQ8+AT8+AW8+AZ8+BC8+BF8+BI8+BL8+BO8+BR8+BU8+BX8+CA8+CD8+CG8+CJ8+CM8+CP8+CS8+CV8+CY8 -> 4515 | K8: 1 | M8: =ROUND(($D$8/$E$3*K8)+($D$8/$H$2*L8),0) -> 645 | N8: 1 | P8: =ROUND(($D$8/$E$3*N8)+($D$8/$H$2*O8),0) -> 645 | Q8: 1 | S8: =ROUND(($D$8/$E$3*Q8)+($D$8/$H$2*R8),0) -> 645 | T8: 1 | V8: =ROUND(($D$8/$E$3*T8)+($D$8/$H$2*U8),0) -> 645 | W8: 1 | Y8: =ROUND(($D$8/$E$3*W8)+($D$8/$H$2*X8),0) -> 645 | Z8: 1 | AB8: =ROUND(($D$8/$E$3*Z8)+($D$8/$H$2*AA8),0) -> 645 | AC8: 1 | AE8: =ROUND(($D$8/$E$3*AC8)+($D$8/$H$2*AD8),0) -> 645 | AH8: =ROUND(($D$8/$E$3*AF8)+($D$8/$H$2*AG8),0) -> 0 | AK8: =ROUND(($D$8/$E$3*AI8)+($D$8/$H$2*AJ8),0) -> 0 | AN8: =ROUND(($D$8/$E$3*AL8)+($D$8/$H$2*AM8),0) -> 0 | AQ8: =ROUND(($D$8/$E$3*AO8)+($D$8/$H$2*AP8),0) -> 0 | AT8: =ROUND(($D$8/$E$3*AR8)+($D$8/$H$2*AS8),0) -> 0 | AW8: =ROUND(($D$8/$E$3*AU8)+($D$8/$H$2*AV8),0) -> 0 | AZ8: =ROUND(($D$8/$E$3*AX8)+($D$8/$H$2*AY8),0) -> 0 | BC8: =ROUND(($D$8/$E$3*BA8)+($D$8/$H$2*BB8),0) -> 0 | BF8: =ROUND(($D$8/$E$3*BD8)+($D$8/$H$2*BE8),0) -> 0 | BI8: =ROUND(($D$8/$E$3*BG8)+($D$8/$H$2*BH8),0) -> 0 | BL8: =ROUND(($D$8/$E$3*BJ8)+($D$8/$H$2*BK8),0) -> 0 | BO8: =ROUND(($D$8/$E$3*BM8)+($D$8/$H$2*BN8),0) -> 0 | BR8: =ROUND(($D$8/$E$3*BP8)+($D$8/$H$2*BQ8),0) -> 0 | BU8: =ROUND(($D$8/$E$3*BS8)+($D$8/$H$2*BT8),0) -> 0 | BX8: =ROUND(($D$8/$E$3*BV8)+($D$8/$H$2*BW8),0) -> 0 | CA8: =ROUND(($D$8/$E$3*BY8)+($D$8/$H$2*BZ8),0) -> 0 | CD8: =ROUND(($D$8/$E$3*CB8)+($D$8/$H$2*CC8),0) -> 0 | CG8: =ROUND(($D$8/$E$3*CE8)+($D$8/$H$2*CF8),0) -> 0 | CJ8: =ROUND(($D$8/$E$3*CH8)+($D$8/$H$2*CI8),0) -> 0 | CM8: =ROUND(($D$8/$E$3*CK8)+($D$8/$H$2*CL8),0) -> 0 | CP8: =ROUND(($D$8/$E$3*CN8)+($D$8/$H$2*CO8),0) -> 0 | CS8: =ROUND(($D$8/$E$3*CQ8)+($D$8/$H$2*CR8),0) -> 0 | CV8: =ROUND(($D$8/$E$3*CT8)+($D$8/$H$2*CU8),0) -> 0 | CY8: =ROUND(($D$8/$E$3*CW8)+($D$8/$H$2*CX8),0) -> 0 | DB8: =ROUND(($D$8/$E$3*CZ8)+($D$8/$H$2*DA8),0) -> 0
A9: 6 | B9: Dharmender Noniya | C9: Stitching/Die | D9: 21400 | E9: =K9+N9+Q9+T9+W9+Z9+AC9+AF9+AI9+AL9+AO9+AR9+AU9+AX9+BA9+BD9+BG9+BJ9+BM9+BP9+BS9+BV9+BY9+CB9+CE9+CH9+CK9+CN9+CQ9+CT9+CW9+CZ9 -> 7 | F9: =ROUND(D9/$F$2*E9,0) -> 4832 | G9: =L9+O9+R9+U9+X9+AA9+AD9+AG9+AJ9+AM9+AP9+AS9+AV9+AY9+BB9+BE9+BH9+BK9+BN9+BQ9+BT9+BW9+BZ9+CC9+CF9+CI9+CL9+CO9+CR9+CU9+CX9+DA8 -> 41 | H9: =ROUND(D9/$H$2*G9,0) -> 3538 | I9: =F9+H9 -> 8370 | J9: =M9+P9+S9+V9+Y9+AB9+AE9+AH9+AK9+AN9+AQ9+AT9+AW9+AZ9+BC9+BF9+BI9+BL9+BO9+BR9+BU9+BX9+CA9+CD9+CG9+CJ9+CM9+CP9+CS9+CV9+CY9 -> 8371 | K9: 1 | L9: 3.5 | M9: =ROUND(($D$9/$E$3*K9)+($D$9/$H$2*L9),0) -> 992 | N9: 1 | O9: 8 | P9: =ROUND(($D$9/$E$3*N9)+($D$9/$H$2*O9),0) -> 1381 | Q9: 1 | R9: 7.5 | S9: =ROUND(($D$9/$E$3*Q9)+($D$9/$H$2*R9),0) -> 1338 | T9: 1 | U9: 3.5 | V9: =ROUND(($D$9/$E$3*T9)+($D$9/$H$2*U9),0) -> 992 | W9: 1 | X9: 7.5 | Y9: =ROUND(($D$9/$E$3*W9)+($D$9/$H$2*X9),0) -> 1338 | Z9: 1 | AA9: 7.5 | AB9: =ROUND(($D$9/$E$3*Z9)+($D$9/$H$2*AA9),0) -> 1338 | AC9: 1 | AD9: 3.5 | AE9: =ROUND(($D$9/$E$3*AC9)+($D$9/$H$2*AD9),0) -> 992 | AH9: =ROUND(($D$9/$E$3*AF9)+($D$9/$H$2*AG9),0) -> 0 | AK9: =ROUND(($D$9/$E$3*AI9)+($D$9/$H$2*AJ9),0) -> 0 | AN9: =ROUND(($D$9/$E$3*AL9)+($D$9/$H$2*AM9),0) -> 0 | AQ9: =ROUND(($D$9/$E$3*AO9)+($D$9/$H$2*AP9),0) -> 0 | AT9: =ROUND(($D$9/$E$3*AR9)+($D$9/$H$2*AS9),0) -> 0 | AW9: =ROUND(($D$9/$E$3*AU9)+($D$9/$H$2*AV9),0) -> 0 | AZ9: =ROUND(($D$9/$E$3*AX9)+($D$9/$H$2*AY9),0) -> 0 | BC9: =ROUND(($D$9/$E$3*BA9)+($D$9/$H$2*BB9),0) -> 0 | BF9: =ROUND(($D$9/$E$3*BD9)+($D$9/$H$2*BE9),0) -> 0 | BI9: =ROUND(($D$9/$E$3*BG9)+($D$9/$H$2*BH9),0) -> 0 | BL9: =ROUND(($D$9/$E$3*BJ9)+($D$9/$H$2*BK9),0) -> 0 | BO9: =ROUND(($D$9/$E$3*BM9)+($D$9/$H$2*BN9),0) -> 0 | BR9: =ROUND(($D$9/$E$3*BP9)+($D$9/$H$2*BQ9),0) -> 0 | BU9: =ROUND(($D$9/$E$3*BS9)+($D$9/$H$2*BT9),0) -> 0 | BX9: =ROUND(($D$9/$E$3*BV9)+($D$9/$H$2*BW9),0) -> 0 | CA9: =ROUND(($D$9/$E$3*BY9)+($D$9/$H$2*BZ9),0) -> 0 | CD9: =ROUND(($D$9/$E$3*CB9)+($D$9/$H$2*CC9),0) -> 0 | CG9: =ROUND(($D$9/$E$3*CE9)+($D$9/$H$2*CF9),0) -> 0 | CJ9: =ROUND(($D$9/$E$3*CH9)+($D$9/$H$2*CI9),0) -> 0 | CM9: =ROUND(($D$9/$E$3*CK9)+($D$9/$H$2*CL9),0) -> 0 | CP9: =ROUND(($D$9/$E$3*CN9)+($D$9/$H$2*CO9),0) -> 0 | CS9: =ROUND(($D$9/$E$3*CQ9)+($D$9/$H$2*CR9),0) -> 0 | CV9: =ROUND(($D$9/$E$3*CT9)+($D$9/$H$2*CU9),0) -> 0 | CY9: =ROUND(($D$9/$E$3*CW9)+($D$9/$H$2*CX9),0) -> 0 | DB9: =ROUND(($D$9/$E$3*CZ9)+($D$9/$H$2*DA9),0) -> 0
A10: 7 | B10: Vijay Shahni | C10: Rotary/RS4 | D10: 20400 | E10: =K10+N10+Q10+T10+W10+Z10+AC10+AF10+AI10+AL10+AO10+AR10+AU10+AX10+BA10+BD10+BG10+BJ10+BM10+BP10+BS10+BV10+BY10+CB10+CE10+CH10+CK10+CN10+CQ10+CT10+CW10+CZ10 -> 7 | F10: =ROUND(D10/$F$2*E10,0) -> 4606 | G10: =L10+O10+R10+U10+X10+AA10+AD10+AG10+AJ10+AM10+AP10+AS10+AV10+AY10+BB10+BE10+BH10+BK10+BN10+BQ10+BT10+BW10+BZ10+CC10+CF10+CI10+CL10+CO10+CR10+CU10+CX10+DA9 -> 22 | H10: =ROUND(D10/$H$2*G10,0) -> 1810 | I10: =F10+H10 -> 6416 | J10: =M10+P10+S10+V10+Y10+AB10+AE10+AH10+AK10+AN10+AQ10+AT10+AW10+AZ10+BC10+BF10+BI10+BL10+BO10+BR10+BU10+BX10+CA10+CD10+CG10+CJ10+CM10+CP10+CS10+CV10+CY10 -> 6416 | K10: 1 | L10: 3.5 | M10: =ROUND(($D$10/$E$3*K10)+($D$10/$H$2*L10),0) -> 946 | N10: 1 | P10: =ROUND(($D$10/$E$3*N10)+($D$10/$H$2*O10),0) -> 658 | Q10: 1 | R10: 3.5 | S10: =ROUND(($D$10/$E$3*Q10)+($D$10/$H$2*R10),0) -> 946 | T10: 1 | U10: 3 | V10: =ROUND(($D$10/$E$3*T10)+($D$10/$H$2*U10),0) -> 905 | W10: 1 | X10: 7.5 | Y10: =ROUND(($D$10/$E$3*W10)+($D$10/$H$2*X10),0) -> 1275 | Z10: 1 | AA10: 1 | AB10: =ROUND(($D$10/$E$3*Z10)+($D$10/$H$2*AA10),0) -> 740 | AC10: 1 | AD10: 3.5 | AE10: =ROUND(($D$10/$E$3*AC10)+($D$10/$H$2*AD10),0) -> 946 | AH10: =ROUND(($D$10/$E$3*AF10)+($D$10/$H$2*AG10),0) -> 0 | AK10: =ROUND(($D$10/$E$3*AI10)+($D$10/$H$2*AJ10),0) -> 0 | AN10: =ROUND(($D$10/$E$3*AL10)+($D$10/$H$2*AM10),0) -> 0 | AQ10: =ROUND(($D$10/$E$3*AO10)+($D$10/$H$2*AP10),0) -> 0 | AT10: =ROUND(($D$10/$E$3*AR10)+($D$10/$H$2*AS10),0) -> 0 | AW10: =ROUND(($D$10/$E$3*AU10)+($D$10/$H$2*AV10),0) -> 0 | AZ10: =ROUND(($D$10/$E$3*AX10)+($D$10/$H$2*AY10),0) -> 0 | BC10: =ROUND(($D$10/$E$3*BA10)+($D$10/$H$2*BB10),0) -> 0 | BF10: =ROUND(($D$10/$E$3*BD10)+($D$10/$H$2*BE10),0) -> 0 | BI10: =ROUND(($D$10/$E$3*BG10)+($D$10/$H$2*BH10),0) -> 0 | BL10: =ROUND(($D$10/$E$3*BJ10)+($D$10/$H$2*BK10),0) -> 0 | BO10: =ROUND(($D$10/$E$3*BM10)+($D$10/$H$2*BN10),0) -> 0 | BR10: =ROUND(($D$10/$E$3*BP10)+($D$10/$H$2*BQ10),0) -> 0 | BU10: =ROUND(($D$10/$E$3*BS10)+($D$10/$H$2*BT10),0) -> 0 | BX10: =ROUND(($D$10/$E$3*BV10)+($D$10/$H$2*BW10),0) -> 0 | CA10: =ROUND(($D$10/$E$3*BY10)+($D$10/$H$2*BZ10),0) -> 0 | CD10: =ROUND(($D$10/$E$3*CB10)+($D$10/$H$2*CC10),0) -> 0 | CG10: =ROUND(($D$10/$E$3*CE10)+($D$10/$H$2*CF10),0) -> 0 | CJ10: =ROUND(($D$10/$E$3*CH10)+($D$10/$H$2*CI10),0) -> 0 | CM10: =ROUND(($D$10/$E$3*CK10)+($D$10/$H$2*CL10),0) -> 0 | CP10: =ROUND(($D$10/$E$3*CN10)+($D$10/$H$2*CO10),0) -> 0 | CS10: =ROUND(($D$10/$E$3*CQ10)+($D$10/$H$2*CR10),0) -> 0 | CV10: =ROUND(($D$10/$E$3*CT10)+($D$10/$H$2*CU10),0) -> 0 | CY10: =ROUND(($D$10/$E$3*CW10)+($D$10/$H$2*CX10),0) -> 0 | DB10: =ROUND(($D$10/$E$3*CZ10)+($D$10/$H$2*DA10),0) -> 0
A11: 8 | B11: Suman | C11: Helper | D11: 13000 | E11: =K11+N11+Q11+T11+W11+Z11+AC11+AF11+AI11+AL11+AO11+AR11+AU11+AX11+BA11+BD11+BG11+BJ11+BM11+BP11+BS11+BV11+BY11+CB11+CE11+CH11+CK11+CN11+CQ11+CT11+CW11+CZ11 -> 5 | F11: =ROUND(D11/$F$2*E11,0) -> 2097 | G11: =L11+O11+R11+U11+X11+AA11+AD11+AG11+AJ11+AM11+AP11+AS11+AV11+AY11+BB11+BE11+BH11+BK11+BN11+BQ11+BT11+BW11+BZ11+CC11+CF11+CI11+CL11+CO11+CR11+CU11+CX11+DA10 -> 9 | H11: =ROUND(D11/$H$2*G11,0) -> 472 | I11: =F11+H11 -> 2569 | J11: =M11+P11+S11+V11+Y11+AB11+AE11+AH11+AK11+AN11+AQ11+AT11+AW11+AZ11+BC11+BF11+BI11+BL11+BO11+BR11+BU11+BX11+CA11+CD11+CG11+CJ11+CM11+CP11+CS11+CV11+CY11 -> 2567 | M11: =ROUND(($D$11/$E$3*K11)+($D$11/$H$2*L11),0) -> 0 | N11: 1 | P11: =ROUND(($D$11/$E$3*N11)+($D$11/$H$2*O11),0) -> 419 | S11: =ROUND(($D$11/$E$3*Q11)+($D$11/$H$2*R11),0) -> 0 | T11: 1 | U11: 2.5 | V11: =ROUND(($D$11/$E$3*T11)+($D$11/$H$2*U11),0) -> 550 | W11: 1 | X11: 2 | Y11: =ROUND(($D$11/$E$3*W11)+($D$11/$H$2*X11),0) -> 524 | Z11: 1 | AA11: 2.5 | AB11: =ROUND(($D$11/$E$3*Z11)+($D$11/$H$2*AA11),0) -> 550 | AC11: 1 | AD11: 2 | AE11: =ROUND(($D$11/$E$3*AC11)+($D$11/$H$2*AD11),0) -> 524 | AH11: =ROUND(($D$11/$E$3*AF11)+($D$11/$H$2*AG11),0) -> 0 | AK11: =ROUND(($D$11/$E$3*AI11)+($D$11/$H$2*AJ11),0) -> 0 | AN11: =ROUND(($D$11/$E$3*AL11)+($D$11/$H$2*AM11),0) -> 0 | AQ11: =ROUND(($D$11/$E$3*AO11)+($D$11/$H$2*AP11),0) -> 0 | AT11: =ROUND(($D$11/$E$3*AR11)+($D$11/$H$2*AS11),0) -> 0 | AW11: =ROUND(($D$11/$E$3*AU11)+($D$11/$H$2*AV11),0) -> 0 | AZ11: =ROUND(($D$11/$E$3*AX11)+($D$11/$H$2*AY11),0) -> 0 | BC11: =ROUND(($D$11/$E$3*BA11)+($D$11/$H$2*BB11),0) -> 0 | BF11: =ROUND(($D$11/$E$3*BD11)+($D$11/$H$2*BE11),0) -> 0 | BI11: =ROUND(($D$11/$E$3*BG11)+($D$11/$H$2*BH11),0) -> 0 | BL11: =ROUND(($D$11/$E$3*BJ11)+($D$11/$H$2*BK11),0) -> 0 | BO11: =ROUND(($D$11/$E$3*BM11)+($D$11/$H$2*BN11),0) -> 0 | BR11: =ROUND(($D$11/$E$3*BP11)+($D$11/$H$2*BQ11),0) -> 0 | BU11: =ROUND(($D$11/$E$3*BS11)+($D$11/$H$2*BT11),0) -> 0 | BX11: =ROUND(($D$11/$E$3*BV11)+($D$11/$H$2*BW11),0) -> 0 | CA11: =ROUND(($D$11/$E$3*BY11)+($D$11/$H$2*BZ11),0) -> 0 | CD11: =ROUND(($D$11/$E$3*CB11)+($D$11/$H$2*CC11),0) -> 0 | CG11: =ROUND(($D$11/$E$3*CE11)+($D$11/$H$2*CF11),0) -> 0 | CJ11: =ROUND(($D$11/$E$3*CH11)+($D$11/$H$2*CI11),0) -> 0 | CM11: =ROUND(($D$11/$E$3*CK11)+($D$11/$H$2*CL11),0) -> 0 | CP11: =ROUND(($D$11/$E$3*CN11)+($D$11/$H$2*CO11),0) -> 0 | CS11: =ROUND(($D$11/$E$3*CQ11)+($D$11/$H$2*CR11),0) -> 0 | CV11: =ROUND(($D$11/$E$3*CT11)+($D$11/$H$2*CU11),0) -> 0 | CY11: =ROUND(($D$11/$E$3*CW11)+($D$11/$H$2*CX11),0) -> 0 | DB11: =ROUND(($D$11/$E$3*CZ11)+($D$11/$H$2*DA11),0) -> 0
A12: 9 | B12: Surender (Pasting) | C12: Operator | D12: 16500 | E12: =K12+N12+Q12+T12+W12+Z12+AC12+AF12+AI12+AL12+AO12+AR12+AU12+AX12+BA12+BD12+BG12+BJ12+BM12+BP12+BS12+BV12+BY12+CB12+CE12+CH12+CK12+CN12+CQ12+CT12+CW12+CZ12 -> 7 | F12: =ROUND(D12/$F$2*E12,0) -> 3726 | G12: =L12+O12+R12+U12+X12+AA12+AD12+AG12+AJ12+AM12+AP12+AS12+AV12+AY12+BB12+BE12+BH12+BK12+BN12+BQ12+BT12+BW12+BZ12+CC12+CF12+CI12+CL12+CO12+CR12+CU12+CX12+DA11 -> 36.5 | H12: =ROUND(D12/$H$2*G12,0) -> 2428 | I12: =F12+H12 -> 6154 | J12: =M12+P12+S12+V12+Y12+AB12+AE12+AH12+AK12+AN12+AQ12+AT12+AW12+AZ12+BC12+BF12+BI12+BL12+BO12+BR12+BU12+BX12+CA12+CD12+CG12+CJ12+CM12+CP12+CS12+CV12+CY12 -> 6154 | K12: 1 | L12: 3.5 | M12: =ROUND(($D$12/$E$3*K12)+($D$12/$H$2*L12),0) -> 765 | N12: 1 | O12: 8 | P12: =ROUND(($D$12/$E$3*N12)+($D$12/$H$2*O12),0) -> 1065 | Q12: 1 | R12: 3.5 | S12: =ROUND(($D$12/$E$3*Q12)+($D$12/$H$2*R12),0) -> 765 | T12: 1 | U12: 7.5 | V12: =ROUND(($D$12/$E$3*T12)+($D$12/$H$2*U12),0) -> 1031 | W12: 1 | X12: 3 | Y12: =ROUND(($D$12/$E$3*W12)+($D$12/$H$2*X12),0) -> 732 | Z12: 1 | AA12: 7.5 | AB12: =ROUND(($D$12/$E$3*Z12)+($D$12/$H$2*AA12),0) -> 1031 | AC12: 1 | AD12: 3.5 | AE12: =ROUND(($D$12/$E$3*AC12)+($D$12/$H$2*AD12),0) -> 765 | AH12: =ROUND(($D$12/$E$3*AF12)+($D$12/$H$2*AG12),0) -> 0 | AK12: =ROUND(($D$12/$E$3*AI12)+($D$12/$H$2*AJ12),0) -> 0 | AN12: =ROUND(($D$12/$E$3*AL12)+($D$12/$H$2*AM12),0) -> 0 | AQ12: =ROUND(($D$12/$E$3*AO12)+($D$12/$H$2*AP12),0) -> 0 | AT12: =ROUND(($D$12/$E$3*AR12)+($D$12/$H$2*AS12),0) -> 0 | AW12: =ROUND(($D$12/$E$3*AU12)+($D$12/$H$2*AV12),0) -> 0 | AZ12: =ROUND(($D$12/$E$3*AX12)+($D$12/$H$2*AY12),0) -> 0 | BC12: =ROUND(($D$12/$E$3*BA12)+($D$12/$H$2*BB12),0) -> 0 | BF12: =ROUND(($D$12/$E$3*BD12)+($D$12/$H$2*BE12),0) -> 0 | BI12: =ROUND(($D$12/$E$3*BG12)+($D$12/$H$2*BH12),0) -> 0 | BL12: =ROUND(($D$12/$E$3*BJ12)+($D$12/$H$2*BK12),0) -> 0 | BO12: =ROUND(($D$12/$E$3*BM12)+($D$12/$H$2*BN12),0) -> 0 | BR12: =ROUND(($D$12/$E$3*BP12)+($D$12/$H$2*BQ12),0) -> 0 | BU12: =ROUND(($D$12/$E$3*BS12)+($D$12/$H$2*BT12),0) -> 0 | BX12: =ROUND(($D$12/$E$3*BV12)+($D$12/$H$2*BW12),0) -> 0 | CA12: =ROUND(($D$12/$E$3*BY12)+($D$12/$H$2*BZ12),0) -> 0 | CD12: =ROUND(($D$12/$E$3*CB12)+($D$12/$H$2*CC12),0) -> 0 | CG12: =ROUND(($D$12/$E$3*CE12)+($D$12/$H$2*CF12),0) -> 0 | CJ12: =ROUND(($D$12/$E$3*CH12)+($D$12/$H$2*CI12),0) -> 0 | CM12: =ROUND(($D$12/$E$3*CK12)+($D$12/$H$2*CL12),0) -> 0 | CP12: =ROUND(($D$12/$E$3*CN12)+($D$12/$H$2*CO12),0) -> 0 | CS12: =ROUND(($D$12/$E$3*CQ12)+($D$12/$H$2*CR12),0) -> 0 | CV12: =ROUND(($D$12/$E$3*CT12)+($D$12/$H$2*CU12),0) -> 0 | CY12: =ROUND(($D$12/$E$3*CW12)+($D$12/$H$2*CX12),0) -> 0 | DB12: =ROUND(($D$12/$E$3*CZ12)+($D$12/$H$2*DA12),0) -> 0
A13: 10 | B13: Kunwar Chand | C13: Die opr. | D13: 22000 | E13: =K13+N13+Q13+T13+W13+Z13+AC13+AF13+AI13+AL13+AO13+AR13+AU13+AX13+BA13+BD13+BG13+BJ13+BM13+BP13+BS13+BV13+BY13+CB13+CE13+CH13+CK13+CN13+CQ13+CT13+CW13+CZ13 -> 7 | F13: =ROUND(D13/$F$2*E13,0) -> 4968 | G13: =L13+O13+R13+U13+X13+AA13+AD13+AG13+AJ13+AM13+AP13+AS13+AV13+AY13+BB13+BE13+BH13+BK13+BN13+BQ13+BT13+BW13+BZ13+CC13+CF13+CI13+CL13+CO13+CR13+CU13+CX13+DA12 -> 21 | H13: =ROUND(D13/$H$2*G13,0) -> 1863 | I13: =F13+H13 -> 6831 | J13: =M13+P13+S13+V13+Y13+AB13+AE13+AH13+AK13+AN13+AQ13+AT13+AW13+AZ13+BC13+BF13+BI13+BL13+BO13+BR13+BU13+BX13+CA13+CD13+CG13+CJ13+CM13+CP13+CS13+CV13+CY13 -> 6830 | K13: 1 | L13: 3.5 | M13: =ROUND(($D$13/$E$3*K13)+($D$13/$H$2*L13),0) -> 1020 | N13: 1 | P13: =ROUND(($D$13/$E$3*N13)+($D$13/$H$2*O13),0) -> 710 | Q13: 1 | R13: 3.5 | S13: =ROUND(($D$13/$E$3*Q13)+($D$13/$H$2*R13),0) -> 1020 | T13: 1 | U13: 3.5 | V13: =ROUND(($D$13/$E$3*T13)+($D$13/$H$2*U13),0) -> 1020 | W13: 1 | X13: 3.5 | Y13: =ROUND(($D$13/$E$3*W13)+($D$13/$H$2*X13),0) -> 1020 | Z13: 1 | AA13: 3.5 | AB13: =ROUND(($D$13/$E$3*Z13)+($D$13/$H$2*AA13),0) -> 1020 | AC13: 1 | AD13: 3.5 | AE13: =ROUND(($D$13/$E$3*AC13)+($D$13/$H$2*AD13),0) -> 1020 | AH13: =ROUND(($D$13/$E$3*AF13)+($D$13/$H$2*AG13),0) -> 0 | AK13: =ROUND(($D$13/$E$3*AI13)+($D$13/$H$2*AJ13),0) -> 0 | AN13: =ROUND(($D$13/$E$3*AL13)+($D$13/$H$2*AM13),0) -> 0 | AQ13: =ROUND(($D$13/$E$3*AO13)+($D$13/$H$2*AP13),0) -> 0 | AT13: =ROUND(($D$13/$E$3*AR13)+($D$13/$H$2*AS13),0) -> 0 | AW13: =ROUND(($D$13/$E$3*AU13)+($D$13/$H$2*AV13),0) -> 0 | AZ13: =ROUND(($D$13/$E$3*AX13)+($D$13/$H$2*AY13),0) -> 0 | BC13: =ROUND(($D$13/$E$3*BA13)+($D$13/$H$2*BB13),0) -> 0 | BF13: =ROUND(($D$13/$E$3*BD13)+($D$13/$H$2*BE13),0) -> 0 | BI13: =ROUND(($D$13/$E$3*BG13)+($D$13/$H$2*BH13),0) -> 0 | BL13: =ROUND(($D$13/$E$3*BJ13)+($D$13/$H$2*BK13),0) -> 0 | BO13: =ROUND(($D$13/$E$3*BM13)+($D$13/$H$2*BN13),0) -> 0 | BR13: =ROUND(($D$13/$E$3*BP13)+($D$13/$H$2*BQ13),0) -> 0 | BU13: =ROUND(($D$13/$E$3*BS13)+($D$13/$H$2*BT13),0) -> 0 | BX13: =ROUND(($D$13/$E$3*BV13)+($D$13/$H$2*BW13),0) -> 0 | CA13: =ROUND(($D$13/$E$3*BY13)+($D$13/$H$2*BZ13),0) -> 0 | CD13: =ROUND(($D$13/$E$3*CB13)+($D$13/$H$2*CC13),0) -> 0 | CG13: =ROUND(($D$13/$E$3*CE13)+($D$13/$H$2*CF13),0) -> 0 | CJ13: =ROUND(($D$13/$E$3*CH13)+($D$13/$H$2*CI13),0) -> 0 | CM13: =ROUND(($D$13/$E$3*CK13)+($D$13/$H$2*CL13),0) -> 0 | CP13: =ROUND(($D$13/$E$3*CN13)+($D$13/$H$2*CO13),0) -> 0 | CS13: =ROUND(($D$13/$E$3*CQ13)+($D$13/$H$2*CR13),0) -> 0 | CV13: =ROUND(($D$13/$E$3*CT13)+($D$13/$H$2*CU13),0) -> 0 | CY13: =ROUND(($D$13/$E$3*CW13)+($D$13/$H$2*CX13),0) -> 0 | DB13: =ROUND(($D$13/$E$3*CZ13)+($D$13/$H$2*DA13),0) -> 0
A14: 11 | B14: Shahrukh | C14: Corr. Opr | D14: 23000 | E14: =K14+N14+Q14+T14+W14+Z14+AC14+AF14+AI14+AL14+AO14+AR14+AU14+AX14+BA14+BD14+BG14+BJ14+BM14+BP14+BS14+BV14+BY14+CB14+CE14+CH14+CK14+CN14+CQ14+CT14+CW14+CZ14 -> 6 | F14: =ROUND(D14/$F$2*E14,0) -> 4452 | G14: =L14+O14+R14+U14+X14+AA14+AD14+AG14+AJ14+AM14+AP14+AS14+AV14+AY14+BB14+BE14+BH14+BK14+BN14+BQ14+BT14+BW14+BZ14+CC14+CF14+CI14+CL14+CO14+CR14+CU14+CX14+DA13 -> 14 | H14: =ROUND(D14/$H$2*G14,0) -> 1298 | I14: =F14+H14 -> 5750 | J14: =M14+P14+S14+V14+Y14+AB14+AE14+AH14+AK14+AN14+AQ14+AT14+AW14+AZ14+BC14+BF14+BI14+BL14+BO14+BR14+BU14+BX14+CA14+CD14+CG14+CJ14+CM14+CP14+CS14+CV14+CY14 -> 5752 | M14: =ROUND(($D$14/$E$3*K14)+($D$14/$H$2*L14),0) -> 0 | N14: 1 | P14: =ROUND(($D$14/$E$3*N14)+($D$14/$H$2*O14),0) -> 742 | Q14: 1 | R14: 3.5 | S14: =ROUND(($D$14/$E$3*Q14)+($D$14/$H$2*R14),0) -> 1067 | T14: 1 | U14: 3.5 | V14: =ROUND(($D$14/$E$3*T14)+($D$14/$H$2*U14),0) -> 1067 | W14: 1 | X14: 3.5 | Y14: =ROUND(($D$14/$E$3*W14)+($D$14/$H$2*X14),0) -> 1067 | Z14: 1 | AA14: 3.5 | AB14: =ROUND(($D$14/$E$3*Z14)+($D$14/$H$2*AA14),0) -> 1067 | AC14: 1 | AE14: =ROUND(($D$14/$E$3*AC14)+($D$14/$H$2*AD14),0) -> 742 | AH14: =ROUND(($D$14/$E$3*AF14)+($D$14/$H$2*AG14),0) -> 0 | AK14: =ROUND(($D$14/$E$3*AI14)+($D$14/$H$2*AJ14),0) -> 0 | AN14: =ROUND(($D$14/$E$3*AL14)+($D$14/$H$2*AM14),0) -> 0 | AQ14: =ROUND(($D$14/$E$3*AO14)+($D$14/$H$2*AP14),0) -> 0 | AT14: =ROUND(($D$14/$E$3*AR14)+($D$14/$H$2*AS14),0) -> 0 | AW14: =ROUND(($D$14/$E$3*AU14)+($D$14/$H$2*AV14),0) -> 0 | AZ14: =ROUND(($D$14/$E$3*AX14)+($D$14/$H$2*AY14),0) -> 0 | BC14: =ROUND(($D$14/$E$3*BA14)+($D$14/$H$2*BB14),0) -> 0 | BF14: =ROUND(($D$14/$E$3*BD14)+($D$14/$H$2*BE14),0) -> 0 | BI14: =ROUND(($D$14/$E$3*BG14)+($D$14/$H$2*BH14),0) -> 0 | BL14: =ROUND(($D$14/$E$3*BJ14)+($D$14/$H$2*BK14),0) -> 0 | BO14: =ROUND(($D$14/$E$3*BM14)+($D$14/$H$2*BN14),0) -> 0 | BR14: =ROUND(($D$14/$E$3*BP14)+($D$14/$H$2*BQ14),0) -> 0 | BU14: =ROUND(($D$14/$E$3*BS14)+($D$14/$H$2*BT14),0) -> 0 | BX14: =ROUND(($D$14/$E$3*BV14)+($D$14/$H$2*BW14),0) -> 0 | CA14: =ROUND(($D$14/$E$3*BY14)+($D$14/$H$2*BZ14),0) -> 0 | CD14: =ROUND(($D$14/$E$3*CB14)+($D$14/$H$2*CC14),0) -> 0 | CG14: =ROUND(($D$14/$E$3*CE14)+($D$14/$H$2*CF14),0) -> 0 | CJ14: =ROUND(($D$14/$E$3*CH14)+($D$14/$H$2*CI14),0) -> 0 | CM14: =ROUND(($D$14/$E$3*CK14)+($D$14/$H$2*CL14),0) -> 0 | CP14: =ROUND(($D$14/$E$3*CN14)+($D$14/$H$2*CO14),0) -> 0 | CS14: =ROUND(($D$14/$E$3*CQ14)+($D$14/$H$2*CR14),0) -> 0 | CV14: =ROUND(($D$14/$E$3*CT14)+($D$14/$H$2*CU14),0) -> 0 | CY14: =ROUND(($D$14/$E$3*CW14)+($D$14/$H$2*CX14),0) -> 0 | DB14: =ROUND(($D$14/$E$3*CZ14)+($D$14/$H$2*DA14),0) -> 0
A15: 12 | B15: Sharafat | C15: Die opr. | D15: 15000 | E15: =K15+N15+Q15+T15+W15+Z15+AC15+AF15+AI15+AL15+AO15+AR15+AU15+AX15+BA15+BD15+BG15+BJ15+BM15+BP15+BS15+BV15+BY15+CB15+CE15+CH15+CK15+CN15+CQ15+CT15+CW15+CZ15 -> 7 | F15: =ROUND(D15/$F$2*E15,0) -> 3387 | G15: =L15+O15+R15+U15+X15+AA15+AD15+AG15+AJ15+AM15+AP15+AS15+AV15+AY15+BB15+BE15+BH15+BK15+BN15+BQ15+BT15+BW15+BZ15+CC15+CF15+CI15+CL15+CO15+CR15+CU15+CX15+DA14 -> 21 | H15: =ROUND(D15/$H$2*G15,0) -> 1270 | I15: =F15+H15 -> 4657 | J15: =M15+P15+S15+V15+Y15+AB15+AE15+AH15+AK15+AN15+AQ15+AT15+AW15+AZ15+BC15+BF15+BI15+BL15+BO15+BR15+BU15+BX15+CA15+CD15+CG15+CJ15+CM15+CP15+CS15+CV15+CY15 -> 4660 | K15: 1 | L15: 3.5 | M15: =ROUND(($D$15/$E$3*K15)+($D$15/$H$2*L15),0) -> 696 | N15: 1 | P15: =ROUND(($D$15/$E$3*N15)+($D$15/$H$2*O15),0) -> 484 | Q15: 1 | R15: 3.5 | S15: =ROUND(($D$15/$E$3*Q15)+($D$15/$H$2*R15),0) -> 696 | T15: 1 | U15: 3.5 | V15: =ROUND(($D$15/$E$3*T15)+($D$15/$H$2*U15),0) -> 696 | W15: 1 | X15: 3.5 | Y15: =ROUND(($D$15/$E$3*W15)+($D$15/$H$2*X15),0) -> 696 | Z15: 1 | AA15: 3.5 | AB15: =ROUND(($D$15/$E$3*Z15)+($D$15/$H$2*AA15),0) -> 696 | AC15: 1 | AD15: 3.5 | AE15: =ROUND(($D$15/$E$3*AC15)+($D$15/$H$2*AD15),0) -> 696 | AH15: =ROUND(($D$15/$E$3*AF15)+($D$15/$H$2*AG15),0) -> 0 | AK15: =ROUND(($D$15/$E$3*AI15)+($D$15/$H$2*AJ15),0) -> 0 | AN15: =ROUND(($D$15/$E$3*AL15)+($D$15/$H$2*AM15),0) -> 0 | AQ15: =ROUND(($D$15/$E$3*AO15)+($D$15/$H$2*AP15),0) -> 0 | AT15: =ROUND(($D$15/$E$3*AR15)+($D$15/$H$2*AS15),0) -> 0 | AW15: =ROUND(($D$15/$E$3*AU15)+($D$15/$H$2*AV15),0) -> 0 | AZ15: =ROUND(($D$15/$E$3*AX15)+($D$15/$H$2*AY15),0) -> 0 | BC15: =ROUND(($D$15/$E$3*BA15)+($D$15/$H$2*BB15),0) -> 0 | BF15: =ROUND(($D$15/$E$3*BD15)+($D$15/$H$2*BE15),0) -> 0 | BI15: =ROUND(($D$15/$E$3*BG15)+($D$15/$H$2*BH15),0) -> 0 | BL15: =ROUND(($D$15/$E$3*BJ15)+($D$15/$H$2*BK15),0) -> 0 | BO15: =ROUND(($D$15/$E$3*BM15)+($D$15/$H$2*BN15),0) -> 0 | BR15: =ROUND(($D$15/$E$3*BP15)+($D$15/$H$2*BQ15),0) -> 0 | BU15: =ROUND(($D$15/$E$3*BS15)+($D$15/$H$2*BT15),0) -> 0 | BX15: =ROUND(($D$15/$E$3*BV15)+($D$15/$H$2*BW15),0) -> 0 | CA15: =ROUND(($D$15/$E$3*BY15)+($D$15/$H$2*BZ15),0) -> 0 | CD15: =ROUND(($D$15/$E$3*CB15)+($D$15/$H$2*CC15),0) -> 0 | CG15: =ROUND(($D$15/$E$3*CE15)+($D$15/$H$2*CF15),0) -> 0 | CJ15: =ROUND(($D$15/$E$3*CH15)+($D$15/$H$2*CI15),0) -> 0 | CM15: =ROUND(($D$15/$E$3*CK15)+($D$15/$H$2*CL15),0) -> 0 | CP15: =ROUND(($D$15/$E$3*CN15)+($D$15/$H$2*CO15),0) -> 0 | CS15: =ROUND(($D$15/$E$3*CQ15)+($D$15/$H$2*CR15),0) -> 0 | CV15: =ROUND(($D$15/$E$3*CT15)+($D$15/$H$2*CU15),0) -> 0 | CY15: =ROUND(($D$15/$E$3*CW15)+($D$15/$H$2*CX15),0) -> 0 | DB15: =ROUND(($D$15/$E$3*CZ15)+($D$15/$H$2*DA15),0) -> 0
A16: 13 | B16: Sanjan | C16: Helper | D16: 13500 | E16: =K16+N16+Q16+T16+W16+Z16+AC16+AF16+AI16+AL16+AO16+AR16+AU16+AX16+BA16+BD16+BG16+BJ16+BM16+BP16+BS16+BV16+BY16+CB16+CE16+CH16+CK16+CN16+CQ16+CT16+CW16+CZ16 -> 7 | F16: =ROUND(D16/$F$2*E16,0) -> 3048 | G16: =L16+O16+R16+U16+X16+AA16+AD16+AG16+AJ16+AM16+AP16+AS16+AV16+AY16+BB16+BE16+BH16+BK16+BN16+BQ16+BT16+BW16+BZ16+CC16+CF16+CI16+CL16+CO16+CR16+CU16+CX16+DA15 -> 27.5 | H16: =ROUND(D16/$H$2*G16,0) -> 1497 | I16: =F16+H16 -> 4545 | J16: =M16+P16+S16+V16+Y16+AB16+AE16+AH16+AK16+AN16+AQ16+AT16+AW16+AZ16+BC16+BF16+BI16+BL16+BO16+BR16+BU16+BX16+CA16+CD16+CG16+CJ16+CM16+CP16+CS16+CV16+CY16 -> 4546 | K16: 1 | L16: 3 | M16: =ROUND(($D$16/$E$3*K16)+($D$16/$H$2*L16),0) -> 599 | N16: 1 | O16: 8 | P16: =ROUND(($D$16/$E$3*N16)+($D$16/$H$2*O16),0) -> 871 | Q16: 1 | R16: 2.5 | S16: =ROUND(($D$16/$E$3*Q16)+($D$16/$H$2*R16),0) -> 572 | T16: 1 | U16: 3.5 | V16: =ROUND(($D$16/$E$3*T16)+($D$16/$H$2*U16),0) -> 626 | W16: 1 | X16: 3.5 | Y16: =ROUND(($D$16/$E$3*W16)+($D$16/$H$2*X16),0) -> 626 | Z16: 1 | AA16: 3.5 | AB16: =ROUND(($D$16/$E$3*Z16)+($D$16/$H$2*AA16),0) -> 626 | AC16: 1 | AD16: 3.5 | AE16: =ROUND(($D$16/$E$3*AC16)+($D$16/$H$2*AD16),0) -> 626 | AH16: =ROUND(($D$16/$E$3*AF16)+($D$16/$H$2*AG16),0) -> 0 | AK16: =ROUND(($D$16/$E$3*AI16)+($D$16/$H$2*AJ16),0) -> 0 | AN16: =ROUND(($D$16/$E$3*AL16)+($D$16/$H$2*AM16),0) -> 0 | AQ16: =ROUND(($D$16/$E$3*AO16)+($D$16/$H$2*AP16),0) -> 0 | AT16: =ROUND(($D$16/$E$3*AR16)+($D$16/$H$2*AS16),0) -> 0 | AW16: =ROUND(($D$16/$E$3*AU16)+($D$16/$H$2*AV16),0) -> 0 | AZ16: =ROUND(($D$16/$E$3*AX16)+($D$16/$H$2*AY16),0) -> 0 | BC16: =ROUND(($D$16/$E$3*BA16)+($D$16/$H$2*BB16),0) -> 0 | BF16: =ROUND(($D$16/$E$3*BD16)+($D$16/$H$2*BE16),0) -> 0 | BI16: =ROUND(($D$16/$E$3*BG16)+($D$16/$H$2*BH16),0) -> 0 | BL16: =ROUND(($D$16/$E$3*BJ16)+($D$16/$H$2*BK16),0) -> 0 | BO16: =ROUND(($D$16/$E$3*BM16)+($D$16/$H$2*BN16),0) -> 0 | BR16: =ROUND(($D$16/$E$3*BP16)+($D$16/$H$2*BQ16),0) -> 0 | BU16: =ROUND(($D$16/$E$3*BS16)+($D$16/$H$2*BT16),0) -> 0 | BX16: =ROUND(($D$16/$E$3*BV16)+($D$16/$H$2*BW16),0) -> 0 | CA16: =ROUND(($D$16/$E$3*BY16)+($D$16/$H$2*BZ16),0) -> 0 | CD16: =ROUND(($D$16/$E$3*CB16)+($D$16/$H$2*CC16),0) -> 0 | CG16: =ROUND(($D$16/$E$3*CE16)+($D$16/$H$2*CF16),0) -> 0 | CJ16: =ROUND(($D$16/$E$3*CH16)+($D$16/$H$2*CI16),0) -> 0 | CM16: =ROUND(($D$16/$E$3*CK16)+($D$16/$H$2*CL16),0) -> 0 | CP16: =ROUND(($D$16/$E$3*CN16)+($D$16/$H$2*CO16),0) -> 0 | CS16: =ROUND(($D$16/$E$3*CQ16)+($D$16/$H$2*CR16),0) -> 0 | CV16: =ROUND(($D$16/$E$3*CT16)+($D$16/$H$2*CU16),0) -> 0 | CY16: =ROUND(($D$16/$E$3*CW16)+($D$16/$H$2*CX16),0) -> 0 | DB16: =ROUND(($D$16/$E$3*CZ16)+($D$16/$H$2*DA16),0) -> 0
A17: 14 | B17: Jubaida | C17: Helper | D17: 13000 | E17: =K17+N17+Q17+T17+W17+Z17+AC17+AF17+AI17+AL17+AO17+AR17+AU17+AX17+BA17+BD17+BG17+BJ17+BM17+BP17+BS17+BV17+BY17+CB17+CE17+CH17+CK17+CN17+CQ17+CT17+CW17+CZ17 -> 7 | F17: =ROUND(D17/$F$2*E17,0) -> 2935 | G17: =L17+O17+R17+U17+X17+AA17+AD17+AG17+AJ17+AM17+AP17+AS17+AV17+AY17+BB17+BE17+BH17+BK17+BN17+BQ17+BT17+BW17+BZ17+CC17+CF17+CI17+CL17+CO17+CR17+CU17+CX17+DA16 -> 25 | H17: =ROUND(D17/$H$2*G17,0) -> 1310 | I17: =F17+H17 -> 4245 | J17: =M17+P17+S17+V17+Y17+AB17+AE17+AH17+AK17+AN17+AQ17+AT17+AW17+AZ17+BC17+BF17+BI17+BL17+BO17+BR17+BU17+BX17+CA17+CD17+CG17+CJ17+CM17+CP17+CS17+CV17+CY17 -> 4248 | K17: 1 | L17: 3 | M17: =ROUND(($D$17/$E$3*K17)+($D$17/$H$2*L17),0) -> 577 | N17: 1 | O17: 8 | P17: =ROUND(($D$17/$E$3*N17)+($D$17/$H$2*O17),0) -> 839 | Q17: 1 | R17: 3 | S17: =ROUND(($D$17/$E$3*Q17)+($D$17/$H$2*R17),0) -> 577 | T17: 1 | U17: 3 | V17: =ROUND(($D$17/$E$3*T17)+($D$17/$H$2*U17),0) -> 577 | W17: 1 | X17: 3 | Y17: =ROUND(($D$17/$E$3*W17)+($D$17/$H$2*X17),0) -> 577 | Z17: 1 | AA17: 3 | AB17: =ROUND(($D$17/$E$3*Z17)+($D$17/$H$2*AA17),0) -> 577 | AC17: 1 | AD17: 2 | AE17: =ROUND(($D$17/$E$3*AC17)+($D$17/$H$2*AD17),0) -> 524 | AH17: =ROUND(($D$17/$E$3*AF17)+($D$17/$H$2*AG17),0) -> 0 | AK17: =ROUND(($D$17/$E$3*AI17)+($D$17/$H$2*AJ17),0) -> 0 | AN17: =ROUND(($D$17/$E$3*AL17)+($D$17/$H$2*AM17),0) -> 0 | AQ17: =ROUND(($D$17/$E$3*AO17)+($D$17/$H$2*AP17),0) -> 0 | AT17: =ROUND(($D$17/$E$3*AR17)+($D$17/$H$2*AS17),0) -> 0 | AW17: =ROUND(($D$17/$E$3*AU17)+($D$17/$H$2*AV17),0) -> 0 | AZ17: =ROUND(($D$17/$E$3*AX17)+($D$17/$H$2*AY17),0) -> 0 | BC17: =ROUND(($D$17/$E$3*BA17)+($D$17/$H$2*BB17),0) -> 0 | BF17: =ROUND(($D$17/$E$3*BD17)+($D$17/$H$2*BE17),0) -> 0 | BI17: =ROUND(($D$17/$E$3*BG17)+($D$17/$H$2*BH17),0) -> 0 | BL17: =ROUND(($D$17/$E$3*BJ17)+($D$17/$H$2*BK17),0) -> 0 | BO17: =ROUND(($D$17/$E$3*BM17)+($D$17/$H$2*BN17),0) -> 0 | BR17: =ROUND(($D$17/$E$3*BP17)+($D$17/$H$2*BQ17),0) -> 0 | BU17: =ROUND(($D$17/$E$3*BS17)+($D$17/$H$2*BT17),0) -> 0 | BX17: =ROUND(($D$17/$E$3*BV17)+($D$17/$H$2*BW17),0) -> 0 | CA17: =ROUND(($D$17/$E$3*BY17)+($D$17/$H$2*BZ17),0) -> 0 | CD17: =ROUND(($D$17/$E$3*CB17)+($D$17/$H$2*CC17),0) -> 0 | CG17: =ROUND(($D$17/$E$3*CE17)+($D$17/$H$2*CF17),0) -> 0 | CJ17: =ROUND(($D$17/$E$3*CH17)+($D$17/$H$2*CI17),0) -> 0 | CM17: =ROUND(($D$17/$E$3*CK17)+($D$17/$H$2*CL17),0) -> 0 | CP17: =ROUND(($D$17/$E$3*CN17)+($D$17/$H$2*CO17),0) -> 0 | CS17: =ROUND(($D$17/$E$3*CQ17)+($D$17/$H$2*CR17),0) -> 0 | CV17: =ROUND(($D$17/$E$3*CT17)+($D$17/$H$2*CU17),0) -> 0 | CY17: =ROUND(($D$17/$E$3*CW17)+($D$17/$H$2*CX17),0) -> 0 | DB17: =ROUND(($D$17/$E$3*CZ17)+($D$17/$H$2*DA17),0) -> 0
A18: 15 | B18: Nitish | C18: Helper | D18: 13500 | E18: =K18+N18+Q18+T18+W18+Z18+AC18+AF18+AI18+AL18+AO18+AR18+AU18+AX18+BA18+BD18+BG18+BJ18+BM18+BP18+BS18+BV18+BY18+CB18+CE18+CH18+CK18+CN18+CQ18+CT18+CW18+CZ18 -> 6 | F18: =ROUND(D18/$F$2*E18,0) -> 2613 | G18: =L18+O18+R18+U18+X18+AA18+AD18+AG18+AJ18+AM18+AP18+AS18+AV18+AY18+BB18+BE18+BH18+BK18+BN18+BQ18+BT18+BW18+BZ18+CC18+CF18+CI18+CL18+CO18+CR18+CU18+CX18+DA17 -> 18.5 | H18: =ROUND(D18/$H$2*G18,0) -> 1007 | I18: =F18+H18 -> 3620 | J18: =M18+P18+S18+V18+Y18+AB18+AE18+AH18+AK18+AN18+AQ18+AT18+AW18+AZ18+BC18+BF18+BI18+BL18+BO18+BR18+BU18+BX18+CA18+CD18+CG18+CJ18+CM18+CP18+CS18+CV18+CY18 -> 3619 | K18: 1 | L18: 3.5 | M18: =ROUND(($D$18/$E$3*K18)+($D$18/$H$2*L18),0) -> 626 | N18: 1 | P18: =ROUND(($D$18/$E$3*N18)+($D$18/$H$2*O18),0) -> 435 | S18: =ROUND(($D$18/$E$3*Q18)+($D$18/$H$2*R18),0) -> 0 | T18: 1 | U18: 3.5 | V18: =ROUND(($D$18/$E$3*T18)+($D$18/$H$2*U18),0) -> 626 | W18: 1 | X18: 3.5 | Y18: =ROUND(($D$18/$E$3*W18)+($D$18/$H$2*X18),0) -> 626 | Z18: 1 | AA18: 3.5 | AB18: =ROUND(($D$18/$E$3*Z18)+($D$18/$H$2*AA18),0) -> 626 | AC18: 1 | AD18: 4.5 | AE18: =ROUND(($D$18/$E$3*AC18)+($D$18/$H$2*AD18),0) -> 680 | AH18: =ROUND(($D$18/$E$3*AF18)+($D$18/$H$2*AG18),0) -> 0 | AK18: =ROUND(($D$18/$E$3*AI18)+($D$18/$H$2*AJ18),0) -> 0 | AN18: =ROUND(($D$18/$E$3*AL18)+($D$18/$H$2*AM18),0) -> 0 | AQ18: =ROUND(($D$18/$E$3*AO18)+($D$18/$H$2*AP18),0) -> 0 | AT18: =ROUND(($D$18/$E$3*AR18)+($D$18/$H$2*AS18),0) -> 0 | AW18: =ROUND(($D$18/$E$3*AU18)+($D$18/$H$2*AV18),0) -> 0 | AZ18: =ROUND(($D$18/$E$3*AX18)+($D$18/$H$2*AY18),0) -> 0 | BC18: =ROUND(($D$18/$E$3*BA18)+($D$18/$H$2*BB18),0) -> 0 | BF18: =ROUND(($D$18/$E$3*BD18)+($D$18/$H$2*BE18),0) -> 0 | BI18: =ROUND(($D$18/$E$3*BG18)+($D$18/$H$2*BH18),0) -> 0 | BL18: =ROUND(($D$18/$E$3*BJ18)+($D$18/$H$2*BK18),0) -> 0 | BO18: =ROUND(($D$18/$E$3*BM18)+($D$18/$H$2*BN18),0) -> 0 | BR18: =ROUND(($D$18/$E$3*BP18)+($D$18/$H$2*BQ18),0) -> 0 | BU18: =ROUND(($D$18/$E$3*BS18)+($D$18/$H$2*BT18),0) -> 0 | BX18: =ROUND(($D$18/$E$3*BV18)+($D$18/$H$2*BW18),0) -> 0 | CA18: =ROUND(($D$18/$E$3*BY18)+($D$18/$H$2*BZ18),0) -> 0 | CD18: =ROUND(($D$18/$E$3*CB18)+($D$18/$H$2*CC18),0) -> 0 | CG18: =ROUND(($D$18/$E$3*CE18)+($D$18/$H$2*CF18),0) -> 0 | CJ18: =ROUND(($D$18/$E$3*CH18)+($D$18/$H$2*CI18),0) -> 0 | CM18: =ROUND(($D$18/$E$3*CK18)+($D$18/$H$2*CL18),0) -> 0 | CP18: =ROUND(($D$18/$E$3*CN18)+($D$18/$H$2*CO18),0) -> 0 | CS18: =ROUND(($D$18/$E$3*CQ18)+($D$18/$H$2*CR18),0) -> 0 | CV18: =ROUND(($D$18/$E$3*CT18)+($D$18/$H$2*CU18),0) -> 0 | CY18: =ROUND(($D$18/$E$3*CW18)+($D$18/$H$2*CX18),0) -> 0 | DB18: =ROUND(($D$18/$E$3*CZ18)+($D$18/$H$2*DA18),0) -> 0
A19: 16 | B19: Priti | C19: Helper | D19: 13000 | E19: =K19+N19+Q19+T19+W19+Z19+AC19+AF19+AI19+AL19+AO19+AR19+AU19+AX19+BA19+BD19+BG19+BJ19+BM19+BP19+BS19+BV19+BY19+CB19+CE19+CH19+CK19+CN19+CQ19+CT19+CW19+CZ19 -> 1 | F19: =ROUND(D19/$F$2*E19,0) -> 419 | G19: =L19+O19+R19+U19+X19+AA19+AD19+AG19+AJ19+AM19+AP19+AS19+AV19+AY19+BB19+BE19+BH19+BK19+BN19+BQ19+BT19+BW19+BZ19+CC19+CF19+CI19+CL19+CO19+CR19+CU19+CX19+DA18 -> 3 | H19: =ROUND(D19/$H$2*G19,0) -> 157 | I19: =F19+H19 -> 576 | J19: =M19+P19+S19+V19+Y19+AB19+AE19+AH19+AK19+AN19+AQ19+AT19+AW19+AZ19+BC19+BF19+BI19+BL19+BO19+BR19+BU19+BX19+CA19+CD19+CG19+CJ19+CM19+CP19+CS19+CV19+CY19 -> 576 | M19: =ROUND(($D$19/$E$3*K19)+($D$19/$H$2*L19),0) -> 0 | N19: 1 | P19: =ROUND(($D$19/$E$3*N19)+($D$19/$H$2*O19),0) -> 419 | R19: 3 | S19: =ROUND(($D$19/$E$3*Q19)+($D$19/$H$2*R19),0) -> 157 | V19: =ROUND(($D$19/$E$3*T19)+($D$19/$H$2*U19),0) -> 0 | Y19: =ROUND(($D$19/$E$3*W19)+($D$19/$H$2*X19),0) -> 0 | AB19: =ROUND(($D$19/$E$3*Z19)+($D$19/$H$2*AA19),0) -> 0 | AE19: =ROUND(($D$19/$E$3*AC19)+($D$19/$H$2*AD19),0) -> 0 | AH19: =ROUND(($D$19/$E$3*AF19)+($D$19/$H$2*AG19),0) -> 0 | AK19: =ROUND(($D$19/$E$3*AI19)+($D$19/$H$2*AJ19),0) -> 0 | AN19: =ROUND(($D$19/$E$3*AL19)+($D$19/$H$2*AM19),0) -> 0 | AQ19: =ROUND(($D$19/$E$3*AO19)+($D$19/$H$2*AP19),0) -> 0 | AT19: =ROUND(($D$19/$E$3*AR19)+($D$19/$H$2*AS19),0) -> 0 | AW19: =ROUND(($D$19/$E$3*AU19)+($D$19/$H$2*AV19),0) -> 0 | AZ19: =ROUND(($D$19/$E$3*AX19)+($D$19/$H$2*AY19),0) -> 0 | BC19: =ROUND(($D$19/$E$3*BA19)+($D$19/$H$2*BB19),0) -> 0 | BF19: =ROUND(($D$19/$E$3*BD19)+($D$19/$H$2*BE19),0) -> 0 | BI19: =ROUND(($D$19/$E$3*BG19)+($D$19/$H$2*BH19),0) -> 0 | BL19: =ROUND(($D$19/$E$3*BJ19)+($D$19/$H$2*BK19),0) -> 0 | BO19: =ROUND(($D$19/$E$3*BM19)+($D$19/$H$2*BN19),0) -> 0 | BR19: =ROUND(($D$19/$E$3*BP19)+($D$19/$H$2*BQ19),0) -> 0 | BU19: =ROUND(($D$19/$E$3*BS19)+($D$19/$H$2*BT19),0) -> 0 | BX19: =ROUND(($D$19/$E$3*BV19)+($D$19/$H$2*BW19),0) -> 0 | CA19: =ROUND(($D$19/$E$3*BY19)+($D$19/$H$2*BZ19),0) -> 0 | CD19: =ROUND(($D$19/$E$3*CB19)+($D$19/$H$2*CC19),0) -> 0 | CG19: =ROUND(($D$19/$E$3*CE19)+($D$19/$H$2*CF19),0) -> 0 | CJ19: =ROUND(($D$19/$E$3*CH19)+($D$19/$H$2*CI19),0) -> 0 | CM19: =ROUND(($D$19/$E$3*CK19)+($D$19/$H$2*CL19),0) -> 0 | CP19: =ROUND(($D$19/$E$3*CN19)+($D$19/$H$2*CO19),0) -> 0 | CS19: =ROUND(($D$19/$E$3*CQ19)+($D$19/$H$2*CR19),0) -> 0 | CV19: =ROUND(($D$19/$E$3*CT19)+($D$19/$H$2*CU19),0) -> 0 | CY19: =ROUND(($D$19/$E$3*CW19)+($D$19/$H$2*CX19),0) -> 0 | DB19: =ROUND(($D$19/$E$3*CZ19)+($D$19/$H$2*DA19),0) -> 0
A20: 17 | B20: Rohit | C20: Helper | D20: 14500 | E20: =K20+N20+Q20+T20+W20+Z20+AC20+AF20+AI20+AL20+AO20+AR20+AU20+AX20+BA20+BD20+BG20+BJ20+BM20+BP20+BS20+BV20+BY20+CB20+CE20+CH20+CK20+CN20+CQ20+CT20+CW20+CZ20 -> 6 | F20: =ROUND(D20/$F$2*E20,0) -> 2806 | G20: =L20+O20+R20+U20+X20+AA20+AD20+AG20+AJ20+AM20+AP20+AS20+AV20+AY20+BB20+BE20+BH20+BK20+BN20+BQ20+BT20+BW20+BZ20+CC20+CF20+CI20+CL20+CO20+CR20+CU20+CX20+DA19 -> 16.5 | H20: =ROUND(D20/$H$2*G20,0) -> 965 | I20: =F20+H20 -> 3771 | J20: =M20+P20+S20+V20+Y20+AB20+AE20+AH20+AK20+AN20+AQ20+AT20+AW20+AZ20+BC20+BF20+BI20+BL20+BO20+BR20+BU20+BX20+CA20+CD20+CG20+CJ20+CM20+CP20+CS20+CV20+CY20 -> 3770 | K20: 1 | L20: 3.5 | M20: =ROUND(($D$20/$E$3*K20)+($D$20/$H$2*L20),0) -> 672 | N20: 1 | P20: =ROUND(($D$20/$E$3*N20)+($D$20/$H$2*O20),0) -> 468 | Q20: 1 | R20: 3.5 | S20: =ROUND(($D$20/$E$3*Q20)+($D$20/$H$2*R20),0) -> 672 | T20: 1 | U20: 3.5 | V20: =ROUND(($D$20/$E$3*T20)+($D$20/$H$2*U20),0) -> 672 | W20: 1 | X20: 3.5 | Y20: =ROUND(($D$20/$E$3*W20)+($D$20/$H$2*X20),0) -> 672 | AB20: =ROUND(($D$20/$E$3*Z20)+($D$20/$H$2*AA20),0) -> 0 | AC20: 1 | AD20: 2.5 | AE20: =ROUND(($D$20/$E$3*AC20)+($D$20/$H$2*AD20),0) -> 614 | AH20: =ROUND(($D$20/$E$3*AF20)+($D$20/$H$2*AG20),0) -> 0 | AK20: =ROUND(($D$20/$E$3*AI20)+($D$20/$H$2*AJ20),0) -> 0 | AN20: =ROUND(($D$20/$E$3*AL20)+($D$20/$H$2*AM20),0) -> 0 | AQ20: =ROUND(($D$20/$E$3*AO20)+($D$20/$H$2*AP20),0) -> 0 | AT20: =ROUND(($D$20/$E$3*AR20)+($D$20/$H$2*AS20),0) -> 0 | AW20: =ROUND(($D$20/$E$3*AU20)+($D$20/$H$2*AV20),0) -> 0 | AZ20: =ROUND(($D$20/$E$3*AX20)+($D$20/$H$2*AY20),0) -> 0 | BC20: =ROUND(($D$20/$E$3*BA20)+($D$20/$H$2*BB20),0) -> 0 | BF20: =ROUND(($D$20/$E$3*BD20)+($D$20/$H$2*BE20),0) -> 0 | BI20: =ROUND(($D$20/$E$3*BG20)+($D$20/$H$2*BH20),0) -> 0 | BL20: =ROUND(($D$20/$E$3*BJ20)+($D$20/$H$2*BK20),0) -> 0 | BO20: =ROUND(($D$20/$E$3*BM20)+($D$20/$H$2*BN20),0) -> 0 | BR20: =ROUND(($D$20/$E$3*BP20)+($D$20/$H$2*BQ20),0) -> 0 | BU20: =ROUND(($D$20/$E$3*BS20)+($D$20/$H$2*BT20),0) -> 0 | BX20: =ROUND(($D$20/$E$3*BV20)+($D$20/$H$2*BW20),0) -> 0 | CA20: =ROUND(($D$20/$E$3*BY20)+($D$20/$H$2*BZ20),0) -> 0 | CD20: =ROUND(($D$20/$E$3*CB20)+($D$20/$H$2*CC20),0) -> 0 | CG20: =ROUND(($D$20/$E$3*CE20)+($D$20/$H$2*CF20),0) -> 0 | CJ20: =ROUND(($D$20/$E$3*CH20)+($D$20/$H$2*CI20),0) -> 0 | CM20: =ROUND(($D$20/$E$3*CK20)+($D$20/$H$2*CL20),0) -> 0 | CP20: =ROUND(($D$20/$E$3*CN20)+($D$20/$H$2*CO20),0) -> 0 | CS20: =ROUND(($D$20/$E$3*CQ20)+($D$20/$H$2*CR20),0) -> 0 | CV20: =ROUND(($D$20/$E$3*CT20)+($D$20/$H$2*CU20),0) -> 0 | CY20: =ROUND(($D$20/$E$3*CW20)+($D$20/$H$2*CX20),0) -> 0 | DB20: =ROUND(($D$20/$E$3*CZ20)+($D$20/$H$2*DA20),0) -> 0
A21: 18 | B21: Sandeep | C21: Operator | D21: 16500 | E21: =K21+N21+Q21+T21+W21+Z21+AC21+AF21+AI21+AL21+AO21+AR21+AU21+AX21+BA21+BD21+BG21+BJ21+BM21+BP21+BS21+BV21+BY21+CB21+CE21+CH21+CK21+CN21+CQ21+CT21+CW21+CZ21 -> 7 | F21: =ROUND(D21/$F$2*E21,0) -> 3726 | G21: =L21+O21+R21+U21+X21+AA21+AD21+AG21+AJ21+AM21+AP21+AS21+AV21+AY21+BB21+BE21+BH21+BK21+BN21+BQ21+BT21+BW21+BZ21+CC21+CF21+CI21+CL21+CO21+CR21+CU21+CX21+DA20 -> 20.5 | H21: =ROUND(D21/$H$2*G21,0) -> 1364 | I21: =F21+H21 -> 5090 | J21: =M21+P21+S21+V21+Y21+AB21+AE21+AH21+AK21+AN21+AQ21+AT21+AW21+AZ21+BC21+BF21+BI21+BL21+BO21+BR21+BU21+BX21+CA21+CD21+CG21+CJ21+CM21+CP21+CS21+CV21+CY21 -> 5089 | K21: 1 | L21: 7.5 | M21: =ROUND(($D$21/$E$3*K21)+($D$21/$H$2*L21),0) -> 1031 | N21: 1 | P21: =ROUND(($D$21/$E$3*N21)+($D$21/$H$2*O21),0) -> 532 | Q21: 1 | S21: =ROUND(($D$21/$E$3*Q21)+($D$21/$H$2*R21),0) -> 532 | T21: 1 | U21: 3.5 | V21: =ROUND(($D$21/$E$3*T21)+($D$21/$H$2*U21),0) -> 765 | W21: 1 | X21: 3.5 | Y21: =ROUND(($D$21/$E$3*W21)+($D$21/$H$2*X21),0) -> 765 | Z21: 1 | AA21: 3.5 | AB21: =ROUND(($D$21/$E$3*Z21)+($D$21/$H$2*AA21),0) -> 765 | AC21: 1 | AD21: 2.5 | AE21: =ROUND(($D$21/$E$3*AC21)+($D$21/$H$2*AD21),0) -> 699 | AH21: =ROUND(($D$21/$E$3*AF21)+($D$21/$H$2*AG21),0) -> 0 | AK21: =ROUND(($D$21/$E$3*AI21)+($D$21/$H$2*AJ21),0) -> 0 | AN21: =ROUND(($D$21/$E$3*AL21)+($D$21/$H$2*AM21),0) -> 0 | AQ21: =ROUND(($D$21/$E$3*AO21)+($D$21/$H$2*AP21),0) -> 0 | AT21: =ROUND(($D$21/$E$3*AR21)+($D$21/$H$2*AS21),0) -> 0 | AW21: =ROUND(($D$21/$E$3*AU21)+($D$21/$H$2*AV21),0) -> 0 | AZ21: =ROUND(($D$21/$E$3*AX21)+($D$21/$H$2*AY21),0) -> 0 | BC21: =ROUND(($D$21/$E$3*BA21)+($D$21/$H$2*BB21),0) -> 0 | BF21: =ROUND(($D$21/$E$3*BD21)+($D$21/$H$2*BE21),0) -> 0 | BI21: =ROUND(($D$21/$E$3*BG21)+($D$21/$H$2*BH21),0) -> 0 | BL21: =ROUND(($D$21/$E$3*BJ21)+($D$21/$H$2*BK21),0) -> 0 | BO21: =ROUND(($D$21/$E$3*BM21)+($D$21/$H$2*BN21),0) -> 0 | BR21: =ROUND(($D$21/$E$3*BP21)+($D$21/$H$2*BQ21),0) -> 0 | BU21: =ROUND(($D$21/$E$3*BS21)+($D$21/$H$2*BT21),0) -> 0 | BX21: =ROUND(($D$21/$E$3*BV21)+($D$21/$H$2*BW21),0) -> 0 | CA21: =ROUND(($D$21/$E$3*BY21)+($D$21/$H$2*BZ21),0) -> 0 | CD21: =ROUND(($D$21/$E$3*CB21)+($D$21/$H$2*CC21),0) -> 0 | CG21: =ROUND(($D$21/$E$3*CE21)+($D$21/$H$2*CF21),0) -> 0 | CJ21: =ROUND(($D$21/$E$3*CH21)+($D$21/$H$2*CI21),0) -> 0 | CM21: =ROUND(($D$21/$E$3*CK21)+($D$21/$H$2*CL21),0) -> 0 | CP21: =ROUND(($D$21/$E$3*CN21)+($D$21/$H$2*CO21),0) -> 0 | CS21: =ROUND(($D$21/$E$3*CQ21)+($D$21/$H$2*CR21),0) -> 0 | CV21: =ROUND(($D$21/$E$3*CT21)+($D$21/$H$2*CU21),0) -> 0 | CY21: =ROUND(($D$21/$E$3*CW21)+($D$21/$H$2*CX21),0) -> 0 | DB21: =ROUND(($D$21/$E$3*CZ21)+($D$21/$H$2*DA21),0) -> 0
A22: 19 | B22: Sonu | C22: Stitching Opr | D22: 18500 | E22: =K22+N22+Q22+T22+W22+Z22+AC22+AF22+AI22+AL22+AO22+AR22+AU22+AX22+BA22+BD22+BG22+BJ22+BM22+BP22+BS22+BV22+BY22+CB22+CE22+CH22+CK22+CN22+CQ22+CT22+CW22+CZ22 -> 7 | F22: =ROUND(D22/$F$2*E22,0) -> 4177 | G22: =L22+O22+R22+U22+X22+AA22+AD22+AG22+AJ22+AM22+AP22+AS22+AV22+AY22+BB22+BE22+BH22+BK22+BN22+BQ22+BT22+BW22+BZ22+CC22+CF22+CI22+CL22+CO22+CR22+CU22+CX22+DA21 -> 33 | H22: =ROUND(D22/$H$2*G22,0) -> 2462 | I22: =F22+H22 -> 6639 | J22: =M22+P22+S22+V22+Y22+AB22+AE22+AH22+AK22+AN22+AQ22+AT22+AW22+AZ22+BC22+BF22+BI22+BL22+BO22+BR22+BU22+BX22+CA22+CD22+CG22+CJ22+CM22+CP22+CS22+CV22+CY22 -> 6639 | K22: 1 | L22: 3.5 | M22: =ROUND(($D$22/$E$3*K22)+($D$22/$H$2*L22),0) -> 858 | N22: 1 | P22: =ROUND(($D$22/$E$3*N22)+($D$22/$H$2*O22),0) -> 597 | Q22: 1 | R22: 7.5 | S22: =ROUND(($D$22/$E$3*Q22)+($D$22/$H$2*R22),0) -> 1156 | T22: 1 | U22: 7.5 | V22: =ROUND(($D$22/$E$3*T22)+($D$22/$H$2*U22),0) -> 1156 | W22: 1 | X22: 3.5 | Y22: =ROUND(($D$22/$E$3*W22)+($D$22/$H$2*X22),0) -> 858 | Z22: 1 | AA22: 7.5 | AB22: =ROUND(($D$22/$E$3*Z22)+($D$22/$H$2*AA22),0) -> 1156 | AC22: 1 | AD22: 3.5 | AE22: =ROUND(($D$22/$E$3*AC22)+($D$22/$H$2*AD22),0) -> 858 | AH22: =ROUND(($D$22/$E$3*AF22)+($D$22/$H$2*AG22),0) -> 0 | AK22: =ROUND(($D$22/$E$3*AI22)+($D$22/$H$2*AJ22),0) -> 0 | AN22: =ROUND(($D$22/$E$3*AL22)+($D$22/$H$2*AM22),0) -> 0 | AQ22: =ROUND(($D$22/$E$3*AO22)+($D$22/$H$2*AP22),0) -> 0 | AT22: =ROUND(($D$22/$E$3*AR22)+($D$22/$H$2*AS22),0) -> 0 | AW22: =ROUND(($D$22/$E$3*AU22)+($D$22/$H$2*AV22),0) -> 0 | AZ22: =ROUND(($D$22/$E$3*AX22)+($D$22/$H$2*AY22),0) -> 0 | BC22: =ROUND(($D$22/$E$3*BA22)+($D$22/$H$2*BB22),0) -> 0 | BF22: =ROUND(($D$22/$E$3*BD22)+($D$22/$H$2*BE22),0) -> 0 | BI22: =ROUND(($D$22/$E$3*BG22)+($D$22/$H$2*BH22),0) -> 0 | BL22: =ROUND(($D$22/$E$3*BJ22)+($D$22/$H$2*BK22),0) -> 0 | BO22: =ROUND(($D$22/$E$3*BM22)+($D$22/$H$2*BN22),0) -> 0 | BR22: =ROUND(($D$22/$E$3*BP22)+($D$22/$H$2*BQ22),0) -> 0 | BU22: =ROUND(($D$22/$E$3*BS22)+($D$22/$H$2*BT22),0) -> 0 | BX22: =ROUND(($D$22/$E$3*BV22)+($D$22/$H$2*BW22),0) -> 0 | CA22: =ROUND(($D$22/$E$3*BY22)+($D$22/$H$2*BZ22),0) -> 0 | CD22: =ROUND(($D$22/$E$3*CB22)+($D$22/$H$2*CC22),0) -> 0 | CG22: =ROUND(($D$22/$E$3*CE22)+($D$22/$H$2*CF22),0) -> 0 | CJ22: =ROUND(($D$22/$E$3*CH22)+($D$22/$H$2*CI22),0) -> 0 | CM22: =ROUND(($D$22/$E$3*CK22)+($D$22/$H$2*CL22),0) -> 0 | CP22: =ROUND(($D$22/$E$3*CN22)+($D$22/$H$2*CO22),0) -> 0 | CS22: =ROUND(($D$22/$E$3*CQ22)+($D$22/$H$2*CR22),0) -> 0 | CV22: =ROUND(($D$22/$E$3*CT22)+($D$22/$H$2*CU22),0) -> 0 | CY22: =ROUND(($D$22/$E$3*CW22)+($D$22/$H$2*CX22),0) -> 0 | DB22: =ROUND(($D$22/$E$3*CZ22)+($D$22/$H$2*DA22),0) -> 0
